Workbook

Sheet FREE (Quick Valuation)
A1: Tapway Global - Valuation Training Dataset | B1: User Inputs | C1: Blue Cells
B2: API-Fetched Data | C2: Yellow Cells
A3: Free Version (Quick Valuation) | B3: Calculated Fields | C3: Green Cells
A5: FREE VERSION - QUICK VALUATION (3-MINUTE ANALYSIS)
A6: USER INPUTS | BJ6: Details/Remarks/Calculation
A7: Field | B7: Apple | C7: Microsoft | D7: Amazon | E7: Alphabet | F7: Meta | G7: Tesla | H7: NVIDIA | I7: Intel | J7: PepsiCo | K7: Nike | L7: Starbucks | M7: Costco | N7: IBM | O7: Oracle | P7: Qualcomm | Q7: AMD | R7: ServiceNow | S7: PayPal | T7: Booking | U7: GM | V7: Target | W7: Lowe’s | X7: Unilever | Y7: BP | Z7: Shell | AA7: Diageo | AB7: HSBC | AC7: RELX | AD7: Ocado | AE7: AstraZeneca | AF7: Siemens | AG7: SAP | AH7: ASML | AI7: LVMH | AJ7: TotalEnergies | AK7: Schneider Electric | AL7: AXA | AM7: Sanofi | AN7: Allianz | AO7: BASF | AP7: BMW | AQ7: Volkswagen | AR7: Adidas | AS7: Infineon | AT7: Nokia | AU7: Barclays | AV7: Lloyds Banking Group | AW7: Standard Chartered | AX7: Vodafone | AY7: BT Group | AZ7: Experian | BA7: Smith & Nephew | BB7: Danone | BC7: Heineken | BD7: Rolls-Royce | BE7: Airbus | BF7: RELX | BG7: RELX Group | BH7: Siemens Energy | BI7: Nestlé
A8: Industry/Sector | B8: Consumer Electronics Brands | C8: Cloud & Hosting | D8: E-Commerce Logistics | E8: Data Platforms & AI Tooling | F8: Digital Media/Performance Agencies | G8: Automotive Suppliers (Tier-1/2/3) | H8: Embedded Software | I8: Embedded Software | J8: Food & Beverage Manufacturing | K8: Apparel & Textiles | L8: Restaurant Groups & QSR | M8: Omnichannel Retailers | N8: IT Services & MSP | O8: Data Platforms & AI Tooling | P8: Embedded Software | Q8: Embedded Software | R8: B2B SaaS | S8: Payment Service Providers (SME) | T8: Travel Agencies & Tour Ops | U8: Automotive Suppliers (Tier-1/2/3) | V8: Omnichannel Retailers | W8: DIY/Building Materials Retail | X8: Household & Cleaning Products | Y8: Fuel Stations & Convenience | Z8: Fuel Stations & Convenience | AA8: Breweries & Beverage Producers | AB8: FX & Brokerage (MiFID firms) | AC8: Publishers & Niche Media | AD8: E-Commerce Logistics | AE8: Pharma Manufacturing (SME) | AF8: Industrial Automation & Robotics | AG8: Vertical SaaS | AH8: Machinery & Equipment | AI8: Personal Care & Cosmetics | AJ8: Fuel Stations & Convenience | AK8: Industrial Automation & Robotics | AL8: Insurance Brokerage (Makler) | AM8: Pharma Manufacturing (SME) | AN8: Insurance Brokerage (Makler) | AO8: Specialty Chemicals | AP8: Automotive Suppliers (Tier-1/2/3) | AQ8: Automotive Suppliers (Tier-1/2/3) | AR8: Sporting Goods | AS8: Embedded Software | AT8: ISPs & Regional Telecoms | AU8: FX & Brokerage (MiFID firms) | AV8: FX & Brokerage (MiFID firms) | AW8: FX & Brokerage (MiFID firms) | AX8: ISPs & Regional Telecoms | AY8: ISPs & Regional Telecoms | AZ8: Data Platforms & AI Tooling | BA8: Medical Devices (SME) | BB8: Food & Beverage Manufacturing | BC8: Breweries & Beverage Producers | BD8: Machinery & Equipment | BE8: Machinery & Equipment | BF8: Publishers & Niche Media | BG8: Publishers & Niche Media | BH8: Grid Services & Electrical Infra | BI8: Food & Beverage Manufacturing | BJ8: Data validation list from =Sector_BaseEBITMultiple[Sector]
A9: Country/Region | B9: US | C9: US | D9: US | E9: US | F9: US | G9: US | H9: US | I9: US | J9: US | K9: US | L9: US | M9: US | N9: US | O9: US | P9: US | Q9: US | R9: US | S9: US | T9: US | U9: US | V9: US | W9: US | X9: UK | Y9: UK | Z9: NL | AA9: UK | AB9: UK | AC9: UK | AD9: UK | AE9: UK | AF9: DE | AG9: DE | AH9: NL | AI9: FR | AJ9: FR | AK9: FR | AL9: FR | AM9: FR | AN9: DE | AO9: DE | AP9: DE | AQ9: DE | AR9: DE | AS9: DE | AT9: FI | AU9: UK | AV9: UK | AW9: UK | AX9: UK | AY9: UK | AZ9: UK | BA9: UK | BB9: FR | BC9: NL | BD9: UK | BE9: FR | BF9: UK | BG9: DE | BH9: NL | BI9: CH | BJ9: ISO code, list from =Country_DeltaMultiple[CountryCode]
A10: Annual Revenue | B10: 274515000000 | C10: 168088000000 | D10: 469822000000 | E10: 257637000000 | F10: 117929000000 | G10: 53823000000 | H10: 11716000000 | I10: 79024000000 | J10: 79474000000 | K10: 44538000000 | L10: 29061000000 | M10: 195929000000 | N10: 57350000000 | O10: 40500000000 | P10: 33600000000 | Q10: 16400000000 | R10: 5896000000 | S10: 25371000000 | T10: 14141000000 | U10: 127004000000 | V10: 93561000000 | W10: 96250000000 | X10: 52444000000 | Y10: 181587000000 | Z10: 261504000000 | AA10: 13870000000 | AB10: 54300000000 | AC10: 7244000000 | AD10: 2300000000 | AE10: 40700000000 | AF10: 62265000000 | AG10: 27839000000 | AH10: 13979000000 | AI10: 64215000000 | AJ10: 205855000000 | AK10: 31100000000 | AL10: 94000000000 | AM10: 41200000000 | AN10: 148500000000 | AO10: 78600000000 | AP10: 111239000000 | AQ10: 250200000000 | AR10: 19844000000 | AS10: 11100000000 | AT10: 23500000000 | AU10: 21900000000 | AV10: 15800000000 | AW10: 15000000000 | AX10: 45580000000 | AY10: 21000000000 | AZ10: 6400000000 | BA10: 4600000000 | BB10: 24300000000 | BC10: 28000000000 | BD10: 11200000000 | BE10: 52100000000 | BF10: 7244000000 | BG10: 27000000000 | BH10: 17400000000 | BI10: 90500000000 | BJ10: Number > 0
A11: EBIT (Operating Profit) | B11: 66288000000 | C11: 69916000000 | D11: 24879000000 | E11: 54396000000 | F11: 32671000000 | G11: 6523000000 | H11: 4224000000 | I11: 21110000000 | J11: 9776000000 | K11: 5727000000 | L11: 4847000000 | M11: 6100000000 | N11: 6500000000 | O11: 12400000000 | P11: 10400000000 | Q11: 2500000000 | R11: 700000000 | S11: 3800000000 | T11: 4100000000 | U11: 6600000000 | V11: 3900000000 | W11: 14100000000 | X11: 8708000000 | Y11: 13001000000 | Z11: 20399000000 | AA11: 3727000000 | AB11: 13200000000 | AC11: 2500000000 | AD11: -300000000 | AE11: 8300000000 | AF11: 6749000000 | AG11: 6709000000 | AH11: 4723000000 | AI11: 14040000000 | AJ11: 30670000000 | AK11: 4800000000 | AL11: 6700000000 | AM11: 9200000000 | AN11: 12300000000 | AO11: 6800000000 | AP11: 12893000000 | AQ11: 19300000000 | AR11: 1990000000 | AS11: 2100000000 | AT11: 2100000000 | AU11: 5000000000 | AV11: 6900000000 | AW11: 2800000000 | AX11: 5200000000 | AY11: 7600000000 | AZ11: 1900000000 | BA11: 800000000 | BB11: 2700000000 | BC11: 3300000000 | BD11: -1200000000 | BE11: 4800000000 | BF11: 2500000000 | BG11: -1500000000 | BH11: 600000000 | BI11: 16500000000 | BJ11: Number ≥ 0 and ≤ Revenue (custom rule)
A12: Currency | B12: USD | C12: USD | D12: USD | E12: USD | F12: USD | G12: USD | H12: USD | I12: USD | J12: USD | K12: USD | L12: USD | M12: USD | N12: USD | O12: USD | P12: USD | Q12: USD | R12: USD | S12: USD | T12: USD | U12: USD | V12: USD | W12: USD | X12: EUR | Y12: USD | Z12: USD | AA12: GBP | AB12: USD | AC12: GBP | AD12: GBP | AE12: USD | AF12: EUR | AG12: EUR | AH12: EUR | AI12: EUR | AJ12: USD | AK12: EUR | AL12: EUR | AM12: EUR | AN12: EUR | AO12: EUR | AP12: EUR | AQ12: EUR | AR12: EUR | AS12: EUR | AT12: EUR | AU12: GBP | AV12: GBP | AW12: USD | AX12: EUR | AY12: GBP | AZ12: USD | BA12: USD | BB12: EUR | BC12: EUR | BD12: GBP | BE12: EUR | BF12: GBP | BG12: EUR | BH12: EUR | BI12: CHF | BJ12: List from =FX_To_EUR[Currency]
A13: Number of Employees (Optional) | B13: 161000 | C13: 221000 | D13: 1525000 | E13: 182000 | F13: 67000 | G13: 140000 | H13: 29600 | I13: 124800 | J13: 318000 | K13: 83700 | L13: 381000 | M13: 316000 | N13: 288000 | O13: 164000 | P13: 51000 | Q13: 26000 | R13: 22000 | S13: 30000 | T13: 24000 | U13: 163000 | V13: 440000 | W13: 300000 | X13: 148000 | Y13: 87800 | Z13: 93000 | AA13: 30000 | AB13: 214000 | AC13: 36000 | AD13: 20000 | AE13: 83100 | AF13: 311000 | AG13: 107000 | AH13: 42000 | AI13: 213000 | AJ13: 101000 | AK13: 168000 | AL13: 93000 | AM13: 91000 | AN13: 159000 | AO13: 111000 | AP13: 154950 | AQ13: 684000 | AR13: 59258 | AS13: 58600 | AT13: 86000 | AU13: 87000 | AV13: 61000 | AW13: 83000 | AX13: 94000 | AY13: 106000 | AZ13: 21700 | BA13: 18000 | BB13: 96000 | BC13: 85000 | BD13: 42000 | BE13: 134000 | BF13: 36000 | BG13: 92000 | BH13: 67000 | BI13: 273000 | BJ13: Number > 0
A14: Top 3 Customers % (Optional) | B14: 25 | C14: 20 | D14: 30 | E14: 35 | F14: 40 | G14: 50 | H14: 40 | I14: 35 | J14: 30 | K14: 45 | L14: 25 | M14: 20 | N14: 35 | O14: 30 | P14: 45 | Q14: 40 | R14: 25 | S14: 50 | T14: 20 | U14: 45 | V14: 25 | W14: 30 | X14: 40 | Y14: 50 | Z14: 55 | AA14: 40 | AB14: 30 | AC14: 25 | AD14: 45 | AE14: 35 | AF14: 30 | AG14: 35 | AH14: 45 | AI14: 25 | AJ14: 50 | AK14: 40 | AL14: 30 | AM14: 35 | AN14: 25 | AO14: 40 | AP14: 45 | AQ14: 50 | AR14: 40 | AS14: 45 | AT14: 35 | AU14: 30 | AV14: 25 | AW14: 30 | AX14: 35 | AY14: 30 | AZ14: 25 | BA14: 40 | BB14: 45 | BC14: 50 | BD14: 50 | BE14: 45 | BF14: 25 | BG14: 55 | BH14: 40 | BI14: 35 | BJ14: Number 0–100.
A15: BACKEND CALCULATIONS
A16: FX Rate to EUR | B16: =VLOOKUP(B12,'Reference Data sheet'!$B$216:$C$222,2,FALSE) -> 0.93 | C16: =VLOOKUP(C12,'Reference Data sheet'!$B$216:$C$222,2,FALSE) -> 0.93 | D16: =VLOOKUP(D12,'Reference Data sheet'!$B$216:$C$222,2,FALSE) -> 0.93 | E16: =VLOOKUP(E12,'Reference Data sheet'!$B$216:$C$222,2,FALSE) -> 0.93 | F16: =VLOOKUP(F12,'Reference Data sheet'!$B$216:$C$222,2,FALSE) -> 0.93 | G16: =VLOOKUP(G12,'Reference Data sheet'!$B$216:$C$222,2,FALSE) -> 0.93 | H16: =VLOOKUP(H12,'Reference Data sheet'!$B$216:$C$222,2,FALSE) -> 0.93 | I16: =VLOOKUP(I12,'Reference Data sheet'!$B$216:$C$222,2,FALSE) -> 0.93 | ... BI16: =VLOOKUP(BI12,'Reference Data sheet'!$B$216:$C$222,2,FALSE) -> 1.04 | BJ16: Lookup from Table 5 - Reference Data Sheet
A17: EBIT (EUR) | B17: =B11*B16 -> 61647840000 | C17: =C11*C16 -> 65021880000 | D17: =D11*D16 -> 23137470000 | E17: =E11*E16 -> 50588280000 | F17: =F11*F16 -> 30384030000 | G17: =G11*G16 -> 6066390000 | H17: =H11*H16 -> 3928320000 | I17: =I11*I16 -> 19632300000 | ... BI17: =BI11*BI16 -> 17160000000 | BJ17: EBIT x FX rate
A18: Base EBIT Multiple | B18: =VLOOKUP(B$8,'Reference Data sheet'!$H$3:$M$176,2,FALSE) -> 11 | C18: =VLOOKUP(C$8,'Reference Data sheet'!$H$3:$M$176,2,FALSE) -> 15 | D18: =VLOOKUP(D$8,'Reference Data sheet'!$H$3:$M$176,2,FALSE) -> 11.5 | E18: =VLOOKUP(E$8,'Reference Data sheet'!$H$3:$M$176,2,FALSE) -> 21.5 | F18: =VLOOKUP(F$8,'Reference Data sheet'!$H$3:$M$176,2,FALSE) -> 10.5 | G18: =VLOOKUP(G$8,'Reference Data sheet'!$H$3:$M$176,2,FALSE) -> 7.5 | H18: =VLOOKUP(H$8,'Reference Data sheet'!$H$3:$M$176,2,FALSE) -> 13 | I18: =VLOOKUP(I$8,'Reference Data sheet'!$H$3:$M$176,2,FALSE) -> 13 | ... BI18: =VLOOKUP(BI$8,'Reference Data sheet'!$H$3:$M$176,2,FALSE) -> 12 | BJ18: Lookup from Table 1 - Reference Data Sheet
A19: Country Risk Factor | B19: =VLOOKUP(B9,'Reference Data sheet'!$B$181:$C$191,2,FALSE) -> 0.2 | C19: =VLOOKUP(C9,'Reference Data sheet'!$B$181:$C$191,2,FALSE) -> 0.2 | D19: =VLOOKUP(D9,'Reference Data sheet'!$B$181:$C$191,2,FALSE) -> 0.2 | E19: =VLOOKUP(E9,'Reference Data sheet'!$B$181:$C$191,2,FALSE) -> 0.2 | F19: =VLOOKUP(F9,'Reference Data sheet'!$B$181:$C$191,2,FALSE) -> 0.2 | G19: =VLOOKUP(G9,'Reference Data sheet'!$B$181:$C$191,2,FALSE) -> 0.2 | H19: =VLOOKUP(H9,'Reference Data sheet'!$B$181:$C$191,2,FALSE) -> 0.2 | I19: =VLOOKUP(I9,'Reference Data sheet'!$B$181:$C$191,2,FALSE) -> 0.2 | ... BI19: =VLOOKUP(BI9,'Reference Data sheet'!$B$181:$C$191,2,FALSE) -> -0.2 | BJ19: Lookup from Table 2 - Reference Data Sheet
A20: Size Adjustment Factor | B20: =IF(B10<'Reference Data sheet'!$B$198,'Reference Data sheet'!$C$197,IF(B10<'Reference Data sheet'!$B$199,'Reference Data sheet'!$C$198,IF(B10<'Reference Data sheet'!$B$200,'Reference Data sheet'!$C$199,IF(B10<'Reference Data sheet'!$B$201,'Reference Data sheet'!$C$200,'Reference Data sheet'!$C$201)))) -> 0.6 | C20: =IF(C10<'Reference Data sheet'!$B$198,'Reference Data sheet'!$C$197,IF(C10<'Reference Data sheet'!$B$199,'Reference Data sheet'!$C$198,IF(C10<'Reference Data sheet'!$B$200,'Reference Data sheet'!$C$199,IF(C10<'Reference Data sheet'!$B$201,'Reference Data sheet'!$C$200,'Reference Data sheet'!$C$201)))) -> 0.6 | D20: =IF(D10<'Reference Data sheet'!$B$198,'Reference Data sheet'!$C$197,IF(D10<'Reference Data sheet'!$B$199,'Reference Data sheet'!$C$198,IF(D10<'Reference Data sheet'!$B$200,'Reference Data sheet'!$C$199,IF(D10<'Reference Data sheet'!$B$201,'Reference Data sheet'!$C$200,'Reference Data sheet'!$C$201)))) -> 0.6 | E20: =IF(E10<'Reference Data sheet'!$B$198,'Reference Data sheet'!$C$197,IF(E10<'Reference Data sheet'!$B$199,'Reference Data sheet'!$C$198,IF(E10<'Reference Data sheet'!$B$200,'Reference Data sheet'!$C$199,IF(E10<'Reference Data sheet'!$B$201,'Reference Data sheet'!$C$200,'Reference Data sheet'!$C$201)))) -> 0.6 | F20: =IF(F10<'Reference Data sheet'!$B$198,'Reference Data sheet'!$C$197,IF(F10<'Reference Data sheet'!$B$199,'Reference Data sheet'!$C$198,IF(F10<'Reference Data sheet'!$B$200,'Reference Data sheet'!$C$199,IF(F10<'Reference Data sheet'!$B$201,'Reference Data sheet'!$C$200,'Reference Data sheet'!$C$201)))) -> 0.6 | G20: =IF(G10<'Reference Data sheet'!$B$198,'Reference Data sheet'!$C$197,IF(G10<'Reference Data sheet'!$B$199,'Reference Data sheet'!$C$198,IF(G10<'Reference Data sheet'!$B$200,'Reference Data sheet'!$C$199,IF(G10<'Reference Data sheet'!$B$201,'Reference Data sheet'!$C$200,'Reference Data sheet'!$C$201)))) -> 0.6 | H20: =IF(H10<'Reference Data sheet'!$B$198,'Reference Data sheet'!$C$197,IF(H10<'Reference Data sheet'!$B$199,'Reference Data sheet'!$C$198,IF(H10<'Reference Data sheet'!$B$200,'Reference Data sheet'!$C$199,IF(H10<'Reference Data sheet'!$B$201,'Reference Data sheet'!$C$200,'Reference Data sheet'!$C$201)))) -> 0.6 | I20: =IF(I10<'Reference Data sheet'!$B$198,'Reference Data sheet'!$C$197,IF(I10<'Reference Data sheet'!$B$199,'Reference Data sheet'!$C$198,IF(I10<'Reference Data sheet'!$B$200,'Reference Data sheet'!$C$199,IF(I10<'Reference Data sheet'!$B$201,'Reference Data sheet'!$C$200,'Reference Data sheet'!$C$201)))) -> 0.6 | ... BI20: =IF(BI10<'Reference Data sheet'!$B$198,'Reference Data sheet'!$C$197,IF(BI10<'Reference Data sheet'!$B$199,'Reference Data sheet'!$C$198,IF(BI10<'Reference Data sheet'!$B$200,'Reference Data sheet'!$C$199,IF(BI10<'Reference Data sheet'!$B$201,'Reference Data sheet'!$C$200,'Reference Data sheet'!$C$201)))) -> 0.6 | BJ20: Lookup from Table 3 - Reference Data Sheet
A21: Customer Concentration Adjustment | B21: =IF(B14<'Reference Data sheet'!$B$208,'Reference Data sheet'!$C$207,IF(B14<'Reference Data sheet'!$B$209,'Reference Data sheet'!$C$208,IF(B14<'Reference Data sheet'!$B$210,'Reference Data sheet'!$C$209,'Reference Data sheet'!$C$210))) -> 0.1 | C21: =IF(C14<'Reference Data sheet'!$B$208,'Reference Data sheet'!$C$207,IF(C14<'Reference Data sheet'!$B$209,'Reference Data sheet'!$C$208,IF(C14<'Reference Data sheet'!$B$210,'Reference Data sheet'!$C$209,'Reference Data sheet'!$C$210))) -> 0.1 | D21: =IF(D14<'Reference Data sheet'!$B$208,'Reference Data sheet'!$C$207,IF(D14<'Reference Data sheet'!$B$209,'Reference Data sheet'!$C$208,IF(D14<'Reference Data sheet'!$B$210,'Reference Data sheet'!$C$209,'Reference Data sheet'!$C$210))) -> 0 | E21: =IF(E14<'Reference Data sheet'!$B$208,'Reference Data sheet'!$C$207,IF(E14<'Reference Data sheet'!$B$209,'Reference Data sheet'!$C$208,IF(E14<'Reference Data sheet'!$B$210,'Reference Data sheet'!$C$209,'Reference Data sheet'!$C$210))) -> 0 | F21: =IF(F14<'Reference Data sheet'!$B$208,'Reference Data sheet'!$C$207,IF(F14<'Reference Data sheet'!$B$209,'Reference Data sheet'!$C$208,IF(F14<'Reference Data sheet'!$B$210,'Reference Data sheet'!$C$209,'Reference Data sheet'!$C$210))) -> 0 | G21: =IF(G14<'Reference Data sheet'!$B$208,'Reference Data sheet'!$C$207,IF(G14<'Reference Data sheet'!$B$209,'Reference Data sheet'!$C$208,IF(G14<'Reference Data sheet'!$B$210,'Reference Data sheet'!$C$209,'Reference Data sheet'!$C$210))) -> -0.3 | H21: =IF(H14<'Reference Data sheet'!$B$208,'Reference Data sheet'!$C$207,IF(H14<'Reference Data sheet'!$B$209,'Reference Data sheet'!$C$208,IF(H14<'Reference Data sheet'!$B$210,'Reference Data sheet'!$C$209,'Reference Data sheet'!$C$210))) -> 0 | I21: =IF(I14<'Reference Data sheet'!$B$208,'Reference Data sheet'!$C$207,IF(I14<'Reference Data sheet'!$B$209,'Reference Data sheet'!$C$208,IF(I14<'Reference Data sheet'!$B$210,'Reference Data sheet'!$C$209,'Reference Data sheet'!$C$210))) -> 0 | ... BI21: =IF(BI14<'Reference Data sheet'!$B$208,'Reference Data sheet'!$C$207,IF(BI14<'Reference Data sheet'!$B$209,'Reference Data sheet'!$C$208,IF(BI14<'Reference Data sheet'!$B$210,'Reference Data sheet'!$C$209,'Reference Data sheet'!$C$210))) -> 0 | BJ21: Lookup from Table 4 - Reference Data Sheet
A22: VALUATION OUTPUT
A23: Calculated Adjusted Multiple | B23: =B18*(1+B19+B20+B21) -> 20.9 | C23: =C18*(1+C19+C20+C21) -> 28.5 | D23: =D18*(1+D19+D20+D21) -> 20.7 | E23: =E18*(1+E19+E20+E21) -> 38.7 | F23: =F18*(1+F19+F20+F21) -> 18.9 | G23: =G18*(1+G19+G20+G21) -> 11.25 | H23: =H18*(1+H19+H20+H21) -> 23.4 | I23: =I18*(1+I19+I20+I21) -> 23.4 | ... BI23: =BI18*(1+BI19+BI20+BI21) -> 16.8 | BJ23: Combine all adjustment factors, If base multiple = 6.5, Country + Size + Concentration = 0.20 - 0.30 6.5×(1−0.10)=5.85 | BK23: format as Number, 2 decimals; show “× EBIT” in UI label (not in formula)
A24: Enterprise Value (Mid-point) | B24: =B17*B23 -> 1288439856000 | C24: =C17*C23 -> 1853123580000 | D24: =D17*D23 -> 478945629000 | E24: =E17*E23 -> 1.9577664e+12 | F24: =F17*F23 -> 574258167000 | G24: =G17*G23 -> 6.8246887e+10 | H24: =H17*H23 -> 91922688000 | I24: =I17*I23 -> 459395820000 | ... BI24: =BI17*BI23 -> 2.88288e+11 | BJ24: EBIT in EUR × Adjusted Multiple
A25: =_xlfn.CONCAT(A24," (000 EUR)") -> #NAME? | B25: =ROUND(B24/1000,0)&"k EUR" -> 1288439856k EUR | C25: =ROUND(C24/1000,0)&"k EUR" -> 1853123580k EUR | D25: =ROUND(D24/1000,0)&"k EUR" -> 478945629k EUR | E25: =ROUND(E24/1000,0)&"k EUR" -> 1957766436k EUR | F25: =ROUND(F24/1000,0)&"k EUR" -> 574258167k EUR | G25: =ROUND(G24/1000,0)&"k EUR" -> 68246888k EUR | H25: =ROUND(H24/1000,0)&"k EUR" -> 91922688k EUR | I25: =ROUND(I24/1000,0)&"k EUR" -> 459395820k EUR | ... BI25: =ROUND(BI24/1000,0)&"k EUR" -> 288288000k EUR
A26: Valuation Range - Low (85%) | B26: 0.85 | C26: 0.85 | D26: 0.85 | E26: 0.85 | F26: 0.85 | G26: 0.85 | H26: 0.85 | I26: 0.85 | J26: 0.85 | K26: 0.85 | L26: 0.85 | M26: 0.85 | N26: 0.85 | O26: 0.85 | P26: 0.85 | Q26: 0.85 | R26: 0.85 | S26: 0.85 | T26: 0.85 | U26: 0.85 | V26: 0.85 | W26: 0.85 | X26: 0.85 | Y26: 0.85 | Z26: 0.85 | AA26: 0.85 | AB26: 0.85 | AC26: 0.85 | AD26: 0.85 | AE26: 0.85 | AF26: 0.85 | AG26: 0.85 | AH26: 0.85 | AI26: 0.85 | AJ26: 0.85 | AK26: 0.85 | AL26: 0.85 | AM26: 0.85 | AN26: 0.85 | AO26: 0.85 | AP26: 0.85 | AQ26: 0.85 | AR26: 0.85 | AS26: 0.85 | AT26: 0.85 | AU26: 0.85 | AV26: 0.85 | AW26: 0.85 | AX26: 0.85 | AY26: 0.85 | AZ26: 0.85 | BA26: 0.85 | BB26: 0.85 | BC26: 0.85 | BD26: 0.85 | BE26: 0.85 | BF26: 0.85 | BG26: 0.85 | BH26: 0.85 | BI26: 0.85 | BJ26: Conservative multiple - 85%
A27: Low (Calculated) | B27: =B$24*B26 -> 1095173877600 | C27: =C$24*C26 -> 1575155043000 | D27: =D$24*D26 -> 407103784650 | E27: =E$24*E26 -> 1.6641015e+12 | F27: =F$24*F26 -> 488119441950 | G27: =G$24*G26 -> 5.8009854e+10 | H27: =H$24*H26 -> 78134284800 | I27: =I$24*I26 -> 390486447000 | ... BI27: =BI$24*BI26 -> 2.450448e+11 | BJ27: =C$22*C23
A28: =_xlfn.CONCAT(A27," (000 EUR)") -> #NAME? | B28: =ROUND(B27/1000,0)&"k EUR" -> 1095173878k EUR | C28: =ROUND(C27/1000,0)&"k EUR" -> 1575155043k EUR | D28: =ROUND(D27/1000,0)&"k EUR" -> 407103785k EUR | E28: =ROUND(E27/1000,0)&"k EUR" -> 1664101471k EUR | F28: =ROUND(F27/1000,0)&"k EUR" -> 488119442k EUR | G28: =ROUND(G27/1000,0)&"k EUR" -> 58009854k EUR | H28: =ROUND(H27/1000,0)&"k EUR" -> 78134285k EUR | I28: =ROUND(I27/1000,0)&"k EUR" -> 390486447k EUR | ... BI28: =ROUND(BI27/1000,0)&"k EUR" -> 245044800k EUR
A29: Valuation Range - High (115%) | B29: 1.15 | C29: 1.15 | D29: 1.15 | E29: 1.15 | F29: 1.15 | G29: 1.15 | H29: 1.15 | I29: 1.15 | J29: 1.15 | K29: 1.15 | L29: 1.15 | M29: 1.15 | N29: 1.15 | O29: 1.15 | P29: 1.15 | Q29: 1.15 | R29: 1.15 | S29: 1.15 | T29: 1.15 | U29: 1.15 | V29: 1.15 | W29: 1.15 | X29: 1.15 | Y29: 1.15 | Z29: 1.15 | AA29: 1.15 | AB29: 1.15 | AC29: 1.15 | AD29: 1.15 | AE29: 1.15 | AF29: 1.15 | AG29: 1.15 | AH29: 1.15 | AI29: 1.15 | AJ29: 1.15 | AK29: 1.15 | AL29: 1.15 | AM29: 1.15 | AN29: 1.15 | AO29: 1.15 | AP29: 1.15 | AQ29: 1.15 | AR29: 1.15 | AS29: 1.15 | AT29: 1.15 | AU29: 1.15 | AV29: 1.15 | AW29: 1.15 | AX29: 1.15 | AY29: 1.15 | AZ29: 1.15 | BA29: 1.15 | BB29: 1.15 | BC29: 1.15 | BD29: 1.15 | BE29: 1.15 | BF29: 1.15 | BG29: 1.15 | BH29: 1.15 | BI29: 1.15 | BJ29: Optimistic multiple - 115%
A30: High (Calculated) | B30: =B$24*B29 -> 1481705834400 | C30: =C$24*C29 -> 2.1310921e+12 | D30: =D$24*D29 -> 550787473350 | E30: =E$24*E29 -> 2.2514314e+12 | F30: =F$24*F29 -> 660396892050 | G30: =G$24*G29 -> 7.8483921e+10 | H30: =H$24*H29 -> 1.0571109e+11 | I30: =I$24*I29 -> 5.2830519e+11 | ... BI30: =BI$24*BI29 -> 3.315312e+11 | BJ30: =C$22*C25
A31: =_xlfn.CONCAT(A30," (000 EUR)") -> #NAME? | B31: =ROUND(B30/1000,0)&"k EUR" -> 1481705834k EUR | C31: =ROUND(C30/1000,0)&"k EUR" -> 2131092117k EUR | D31: =ROUND(D30/1000,0)&"k EUR" -> 550787473k EUR | E31: =ROUND(E30/1000,0)&"k EUR" -> 2251431401k EUR | F31: =ROUND(F30/1000,0)&"k EUR" -> 660396892k EUR | G31: =ROUND(G30/1000,0)&"k EUR" -> 78483921k EUR | H31: =ROUND(H30/1000,0)&"k EUR" -> 105711091k EUR | I31: =ROUND(I30/1000,0)&"k EUR" -> 528305193k EUR | ... BI31: =ROUND(BI30/1000,0)&"k EUR" -> 331531200k EUR
A32: Risk Comment | B32: =IF( _xlfn.TEXTJOIN(" | ",TRUE, IF(B14>=60,"Very high customer concentration",""), IF(AND(B14<60,B14>=45),"High customer concentration",""), IF(B11/B10<0.05,"Very low profitability",""), IF(B19<=-0.4,"Elevated country risk","") )="", "No major concentration risk", _xlfn.TEXTJOIN(" | ",TRUE, IF(B14>=60,"Very high customer concentration",""), IF(AND(B14<60,B14>=45),"High customer concentration",""), IF(B11/B10<0.05,"Very low profitability",""), IF(B19<=-0.4,"Elevated country risk","") ) ) -> #NAME? | C32: =IF( _xlfn.TEXTJOIN(" | ",TRUE, IF(C14>=60,"Very high customer concentration",""), IF(AND(C14<60,C14>=45),"High customer concentration",""), IF(C11/C10<0.05,"Very low profitability",""), IF(C19<=-0.4,"Elevated country risk","") )="", "No major concentration risk", _xlfn.TEXTJOIN(" | ",TRUE, IF(C14>=60,"Very high customer concentration",""), IF(AND(C14<60,C14>=45),"High customer concentration",""), IF(C11/C10<0.05,"Very low profitability",""), IF(C19<=-0.4,"Elevated country risk","") ) ) -> #NAME? | D32: =IF( _xlfn.TEXTJOIN(" | ",TRUE, IF(D14>=60,"Very high customer concentration",""), IF(AND(D14<60,D14>=45),"High customer concentration",""), IF(D11/D10<0.05,"Very low profitability",""), IF(D19<=-0.4,"Elevated country risk","") )="", "No major concentration risk", _xlfn.TEXTJOIN(" | ",TRUE, IF(D14>=60,"Very high customer concentration",""), IF(AND(D14<60,D14>=45),"High customer concentration",""), IF(D11/D10<0.05,"Very low profitability",""), IF(D19<=-0.4,"Elevated country risk","") ) ) -> #NAME? | E32: =IF( _xlfn.TEXTJOIN(" | ",TRUE, IF(E14>=60,"Very high customer concentration",""), IF(AND(E14<60,E14>=45),"High customer concentration",""), IF(E11/E10<0.05,"Very low profitability",""), IF(E19<=-0.4,"Elevated country risk","") )="", "No major concentration risk", _xlfn.TEXTJOIN(" | ",TRUE, IF(E14>=60,"Very high customer concentration",""), IF(AND(E14<60,E14>=45),"High customer concentration",""), IF(E11/E10<0.05,"Very low profitability",""), IF(E19<=-0.4,"Elevated country risk","") ) ) -> #NAME? | F32: =IF( _xlfn.TEXTJOIN(" | ",TRUE, IF(F14>=60,"Very high customer concentration",""), IF(AND(F14<60,F14>=45),"High customer concentration",""), IF(F11/F10<0.05,"Very low profitability",""), IF(F19<=-0.4,"Elevated country risk","") )="", "No major concentration risk", _xlfn.TEXTJOIN(" | ",TRUE, IF(F14>=60,"Very high customer concentration",""), IF(AND(F14<60,F14>=45),"High customer concentration",""), IF(F11/F10<0.05,"Very low profitability",""), IF(F19<=-0.4,"Elevated country risk","") ) ) -> #NAME? | G32: =IF( _xlfn.TEXTJOIN(" | ",TRUE, IF(G14>=60,"Very high customer concentration",""), IF(AND(G14<60,G14>=45),"High customer concentration",""), IF(G11/G10<0.05,"Very low profitability",""), IF(G19<=-0.4,"Elevated country risk","") )="", "No major concentration risk", _xlfn.TEXTJOIN(" | ",TRUE, IF(G14>=60,"Very high customer concentration",""), IF(AND(G14<60,G14>=45),"High customer concentration",""), IF(G11/G10<0.05,"Very low profitability",""), IF(G19<=-0.4,"Elevated country risk","") ) ) -> #NAME? | H32: =IF( _xlfn.TEXTJOIN(" | ",TRUE, IF(H14>=60,"Very high customer concentration",""), IF(AND(H14<60,H14>=45),"High customer concentration",""), IF(H11/H10<0.05,"Very low profitability",""), IF(H19<=-0.4,"Elevated country risk","") )="", "No major concentration risk", _xlfn.TEXTJOIN(" | ",TRUE, IF(H14>=60,"Very high customer concentration",""), IF(AND(H14<60,H14>=45),"High customer concentration",""), IF(H11/H10<0.05,"Very low profitability",""), IF(H19<=-0.4,"Elevated country risk","") ) ) -> #NAME? | I32: =IF( _xlfn.TEXTJOIN(" | ",TRUE, IF(I14>=60,"Very high customer concentration",""), IF(AND(I14<60,I14>=45),"High customer concentration",""), IF(I11/I10<0.05,"Very low profitability",""), IF(I19<=-0.4,"Elevated country risk","") )="", "No major concentration risk", _xlfn.TEXTJOIN(" | ",TRUE, IF(I14>=60,"Very high customer concentration",""), IF(AND(I14<60,I14>=45),"High customer concentration",""), IF(I11/I10<0.05,"Very low profitability",""), IF(I19<=-0.4,"Elevated country risk","") ) ) -> #NAME? | ... BI32: =IF( _xlfn.TEXTJOIN(" | ",TRUE, IF(BI14>=60,"Very high customer concentration",""), IF(AND(BI14<60,BI14>=45),"High customer concentration",""), IF(BI11/BI10<0.05,"Very low profitability",""), IF(BI19<=-0.4,"Elevated country risk","") )="", "No major concentration risk", _xlfn.TEXTJOIN(" | ",TRUE, IF(BI14>=60,"Very high customer concentration",""), IF(AND(BI14<60,BI14>=45),"High customer concentration",""), IF(BI11/BI10<0.05,"Very low profitability",""), IF(BI19<=-0.4,"Elevated country risk","") ) ) -> #NAME? | BK32: Conditional formatting - If cell contains "Very high" or "High" → orange/red font
A33: Plausibility Check | B33: =IF(OR(B10<=0,B11<0,B14>100,B14<0), "FAIL", IF(OR(B11/B10<0.03,B11/B10>0.45,IF(B13>0,B10/B13,9999999)<50000,IF(B13>0,B10/B13,9999999)>2500000), "REVIEW", "PASS")) -> PASS | C33: =IF(OR(C10<=0,C11<0,C14>100,C14<0), "FAIL", IF(OR(C11/C10<0.03,C11/C10>0.45,IF(C13>0,C10/C13,9999999)<50000,IF(C13>0,C10/C13,9999999)>2500000), "REVIEW", "PASS")) -> PASS | D33: =IF(OR(D10<=0,D11<0,D14>100,D14<0), "FAIL", IF(OR(D11/D10<0.03,D11/D10>0.45,IF(D13>0,D10/D13,9999999)<50000,IF(D13>0,D10/D13,9999999)>2500000), "REVIEW", "PASS")) -> PASS | E33: =IF(OR(E10<=0,E11<0,E14>100,E14<0), "FAIL", IF(OR(E11/E10<0.03,E11/E10>0.45,IF(E13>0,E10/E13,9999999)<50000,IF(E13>0,E10/E13,9999999)>2500000), "REVIEW", "PASS")) -> PASS | F33: =IF(OR(F10<=0,F11<0,F14>100,F14<0), "FAIL", IF(OR(F11/F10<0.03,F11/F10>0.45,IF(F13>0,F10/F13,9999999)<50000,IF(F13>0,F10/F13,9999999)>2500000), "REVIEW", "PASS")) -> PASS | G33: =IF(OR(G10<=0,G11<0,G14>100,G14<0), "FAIL", IF(OR(G11/G10<0.03,G11/G10>0.45,IF(G13>0,G10/G13,9999999)<50000,IF(G13>0,G10/G13,9999999)>2500000), "REVIEW", "PASS")) -> PASS | H33: =IF(OR(H10<=0,H11<0,H14>100,H14<0), "FAIL", IF(OR(H11/H10<0.03,H11/H10>0.45,IF(H13>0,H10/H13,9999999)<50000,IF(H13>0,H10/H13,9999999)>2500000), "REVIEW", "PASS")) -> PASS | I33: =IF(OR(I10<=0,I11<0,I14>100,I14<0), "FAIL", IF(OR(I11/I10<0.03,I11/I10>0.45,IF(I13>0,I10/I13,9999999)<50000,IF(I13>0,I10/I13,9999999)>2500000), "REVIEW", "PASS")) -> PASS | ... BI33: =IF(OR(BI10<=0,BI11<0,BI14>100,BI14<0), "FAIL", IF(OR(BI11/BI10<0.03,BI11/BI10>0.45,IF(BI13>0,BI10/BI13,9999999)<50000,IF(BI13>0,BI10/BI13,9999999)>2500000), "REVIEW", "PASS")) -> PASS | BK33: Conditional formatting (traffic light)
A34: Acquisition Score (0-100) | B34: =MAX(0,MIN(100,ROUND( 100*( 0.3* IF(B10>0, IF(B11/B10<=0,0, IF(B11/B10<=0.05,0.2*(B11/B10/0.05), IF(B11/B10<=0.15,0.2+0.4*((B11/B10-0.05)/0.1), IF(B11/B10<=0.25,0.6+0.3*((B11/B10-0.15)/0.1), IF(B11/B10>=0.3,1,0.9+0.1*((B11/B10-0.25)/0.05)) ) ) ) ),0) + 0.25* IF(B14>=60,0, IF(B14>=45,0.3+(0-0.3)*((B14-45)/15), IF(B14>=30,0.7+(0.3-0.7)*((B14-30)/15),1) ) ) + 0.25* IF(B10*B15<5000000,0.2, IF(B10*B15<15000000,0.5, IF(B10*B15<50000000,0.7, IF(B10*B15<100000000,0.9,1) ) ) ) + 0.2* IF(B18<=-0.3,0.2, IF(B18<0,0.2+(0.6-0.2)*((B18+0.3)/0.3), IF(B18<0.2,0.6+(0.8-0.6)*(B18/0.2), IF(B18>=0.4,1,0.8+(1-0.8)*((B18-0.2)/0.2)) ) ) ) ),0))) -> 76 | C34: =MAX(0,MIN(100,ROUND( 100*( 0.3* IF(C10>0, IF(C11/C10<=0,0, IF(C11/C10<=0.05,0.2*(C11/C10/0.05), IF(C11/C10<=0.15,0.2+0.4*((C11/C10-0.05)/0.1), IF(C11/C10<=0.25,0.6+0.3*((C11/C10-0.15)/0.1), IF(C11/C10>=0.3,1,0.9+0.1*((C11/C10-0.25)/0.05)) ) ) ) ),0) + 0.25* IF(C14>=60,0, IF(C14>=45,0.3+(0-0.3)*((C14-45)/15), IF(C14>=30,0.7+(0.3-0.7)*((C14-30)/15),1) ) ) + 0.25* IF(C10*C15<5000000,0.2, IF(C10*C15<15000000,0.5, IF(C10*C15<50000000,0.7, IF(C10*C15<100000000,0.9,1) ) ) ) + 0.2* IF(C18<=-0.3,0.2, IF(C18<0,0.2+(0.6-0.2)*((C18+0.3)/0.3), IF(C18<0.2,0.6+(0.8-0.6)*(C18/0.2), IF(C18>=0.4,1,0.8+(1-0.8)*((C18-0.2)/0.2)) ) ) ) ),0))) -> 80 | D34: =MAX(0,MIN(100,ROUND( 100*( 0.3* IF(D10>0, IF(D11/D10<=0,0, IF(D11/D10<=0.05,0.2*(D11/D10/0.05), IF(D11/D10<=0.15,0.2+0.4*((D11/D10-0.05)/0.1), IF(D11/D10<=0.25,0.6+0.3*((D11/D10-0.15)/0.1), IF(D11/D10>=0.3,1,0.9+0.1*((D11/D10-0.25)/0.05)) ) ) ) ),0) + 0.25* IF(D14>=60,0, IF(D14>=45,0.3+(0-0.3)*((D14-45)/15), IF(D14>=30,0.7+(0.3-0.7)*((D14-30)/15),1) ) ) + 0.25* IF(D10*D15<5000000,0.2, IF(D10*D15<15000000,0.5, IF(D10*D15<50000000,0.7, IF(D10*D15<100000000,0.9,1) ) ) ) + 0.2* IF(D18<=-0.3,0.2, IF(D18<0,0.2+(0.6-0.2)*((D18+0.3)/0.3), IF(D18<0.2,0.6+(0.8-0.6)*(D18/0.2), IF(D18>=0.4,1,0.8+(1-0.8)*((D18-0.2)/0.2)) ) ) ) ),0))) -> 49 | E34: =MAX(0,MIN(100,ROUND( 100*( 0.3* IF(E10>0, IF(E11/E10<=0,0, IF(E11/E10<=0.05,0.2*(E11/E10/0.05), IF(E11/E10<=0.15,0.2+0.4*((E11/E10-0.05)/0.1), IF(E11/E10<=0.25,0.6+0.3*((E11/E10-0.15)/0.1), IF(E11/E10>=0.3,1,0.9+0.1*((E11/E10-0.25)/0.05)) ) ) ) ),0) + 0.25* IF(E14>=60,0, IF(E14>=45,0.3+(0-0.3)*((E14-45)/15), IF(E14>=30,0.7+(0.3-0.7)*((E14-30)/15),1) ) ) + 0.25* IF(E10*E15<5000000,0.2, IF(E10*E15<15000000,0.5, IF(E10*E15<50000000,0.7, IF(E10*E15<100000000,0.9,1) ) ) ) + 0.2* IF(E18<=-0.3,0.2, IF(E18<0,0.2+(0.6-0.2)*((E18+0.3)/0.3), IF(E18<0.2,0.6+(0.8-0.6)*(E18/0.2), IF(E18>=0.4,1,0.8+(1-0.8)*((E18-0.2)/0.2)) ) ) ) ),0))) -> 63 | F34: =MAX(0,MIN(100,ROUND( 100*( 0.3* IF(F10>0, IF(F11/F10<=0,0, IF(F11/F10<=0.05,0.2*(F11/F10/0.05), IF(F11/F10<=0.15,0.2+0.4*((F11/F10-0.05)/0.1), IF(F11/F10<=0.25,0.6+0.3*((F11/F10-0.15)/0.1), IF(F11/F10>=0.3,1,0.9+0.1*((F11/F10-0.25)/0.05)) ) ) ) ),0) + 0.25* IF(F14>=60,0, IF(F14>=45,0.3+(0-0.3)*((F14-45)/15), IF(F14>=30,0.7+(0.3-0.7)*((F14-30)/15),1) ) ) + 0.25* IF(F10*F15<5000000,0.2, IF(F10*F15<15000000,0.5, IF(F10*F15<50000000,0.7, IF(F10*F15<100000000,0.9,1) ) ) ) + 0.2* IF(F18<=-0.3,0.2, IF(F18<0,0.2+(0.6-0.2)*((F18+0.3)/0.3), IF(F18<0.2,0.6+(0.8-0.6)*(F18/0.2), IF(F18>=0.4,1,0.8+(1-0.8)*((F18-0.2)/0.2)) ) ) ) ),0))) -> 64 | G34: =MAX(0,MIN(100,ROUND( 100*( 0.3* IF(G10>0, IF(G11/G10<=0,0, IF(G11/G10<=0.05,0.2*(G11/G10/0.05), IF(G11/G10<=0.15,0.2+0.4*((G11/G10-0.05)/0.1), IF(G11/G10<=0.25,0.6+0.3*((G11/G10-0.15)/0.1), IF(G11/G10>=0.3,1,0.9+0.1*((G11/G10-0.25)/0.05)) ) ) ) ),0) + 0.25* IF(G14>=60,0, IF(G14>=45,0.3+(0-0.3)*((G14-45)/15), IF(G14>=30,0.7+(0.3-0.7)*((G14-30)/15),1) ) ) + 0.25* IF(G10*G15<5000000,0.2, IF(G10*G15<15000000,0.5, IF(G10*G15<50000000,0.7, IF(G10*G15<100000000,0.9,1) ) ) ) + 0.2* IF(G18<=-0.3,0.2, IF(G18<0,0.2+(0.6-0.2)*((G18+0.3)/0.3), IF(G18<0.2,0.6+(0.8-0.6)*(G18/0.2), IF(G18>=0.4,1,0.8+(1-0.8)*((G18-0.2)/0.2)) ) ) ) ),0))) -> 45 | H34: =MAX(0,MIN(100,ROUND( 100*( 0.3* IF(H10>0, IF(H11/H10<=0,0, IF(H11/H10<=0.05,0.2*(H11/H10/0.05), IF(H11/H10<=0.15,0.2+0.4*((H11/H10-0.05)/0.1), IF(H11/H10<=0.25,0.6+0.3*((H11/H10-0.15)/0.1), IF(H11/H10>=0.3,1,0.9+0.1*((H11/H10-0.25)/0.05)) ) ) ) ),0) + 0.25* IF(H14>=60,0, IF(H14>=45,0.3+(0-0.3)*((H14-45)/15), IF(H14>=30,0.7+(0.3-0.7)*((H14-30)/15),1) ) ) + 0.25* IF(H10*H15<5000000,0.2, IF(H10*H15<15000000,0.5, IF(H10*H15<50000000,0.7, IF(H10*H15<100000000,0.9,1) ) ) ) + 0.2* IF(H18<=-0.3,0.2, IF(H18<0,0.2+(0.6-0.2)*((H18+0.3)/0.3), IF(H18<0.2,0.6+(0.8-0.6)*(H18/0.2), IF(H18>=0.4,1,0.8+(1-0.8)*((H18-0.2)/0.2)) ) ) ) ),0))) -> 66 | I34: =MAX(0,MIN(100,ROUND( 100*( 0.3* IF(I10>0, IF(I11/I10<=0,0, IF(I11/I10<=0.05,0.2*(I11/I10/0.05), IF(I11/I10<=0.15,0.2+0.4*((I11/I10-0.05)/0.1), IF(I11/I10<=0.25,0.6+0.3*((I11/I10-0.15)/0.1), IF(I11/I10>=0.3,1,0.9+0.1*((I11/I10-0.25)/0.05)) ) ) ) ),0) + 0.25* IF(I14>=60,0, IF(I14>=45,0.3+(0-0.3)*((I14-45)/15), IF(I14>=30,0.7+(0.3-0.7)*((I14-30)/15),1) ) ) + 0.25* IF(I10*I15<5000000,0.2, IF(I10*I15<15000000,0.5, IF(I10*I15<50000000,0.7, IF(I10*I15<100000000,0.9,1) ) ) ) + 0.2* IF(I18<=-0.3,0.2, IF(I18<0,0.2+(0.6-0.2)*((I18+0.3)/0.3), IF(I18<0.2,0.6+(0.8-0.6)*(I18/0.2), IF(I18>=0.4,1,0.8+(1-0.8)*((I18-0.2)/0.2)) ) ) ) ),0))) -> 67 | ... BI34: =MAX(0,MIN(100,ROUND( 100*( 0.3* IF(BI10>0, IF(BI11/BI10<=0,0, IF(BI11/BI10<=0.05,0.2*(BI11/BI10/0.05), IF(BI11/BI10<=0.15,0.2+0.4*((BI11/BI10-0.05)/0.1), IF(BI11/BI10<=0.25,0.6+0.3*((BI11/BI10-0.15)/0.1), IF(BI11/BI10>=0.3,1,0.9+0.1*((BI11/BI10-0.25)/0.05)) ) ) ) ),0) + 0.25* IF(BI14>=60,0, IF(BI14>=45,0.3+(0-0.3)*((BI14-45)/15), IF(BI14>=30,0.7+(0.3-0.7)*((BI14-30)/15),1) ) ) + 0.25* IF(BI10*BI15<5000000,0.2, IF(BI10*BI15<15000000,0.5, IF(BI10*BI15<50000000,0.7, IF(BI10*BI15<100000000,0.9,1) ) ) ) + 0.2* IF(BI18<=-0.3,0.2, IF(BI18<0,0.2+(0.6-0.2)*((BI18+0.3)/0.3), IF(BI18<0.2,0.6+(0.8-0.6)*(BI18/0.2), IF(BI18>=0.4,1,0.8+(1-0.8)*((BI18-0.2)/0.2)) ) ) ) ),0))) -> 60 | BK34: Conditional formatting - 0–49 red, 50–69 amber, 70–84 green, 85–100 dark green

Sheet Reference Data sheet
B3: sector_id | C3: sector_en | D3: sector_de | E3: subsector_id | F3: subsector_en | G3: subsector_de | H3: Subsector_Name (Updated) | I3: Base_EBIT_Multiple | J3: Target_EBIT_Margin_% | K3: Target_CAGR_% | L3: BandMin | M3: Score
B4: TECH | C4: Technology | D4: Technologie | E4: TECH:SaaS_B2B | F4: B2B SaaS | G4: B2Bâ€‘SaaS | H4: B2B SaaS | I4: 17.5 | J4: 32.5 | K4: 17.5 | L4: 10 | M4: 85
B5: TECH | C5: Technology | D5: Technologie | E5: TECH:SaaS_Vert | F5: Vertical SaaS | G5: Vertikales SaaS | H5: Vertical SaaS | I5: 15 | J5: 28.5 | K5: 21.5 | L5: 12 | M5: 82
B6: TECH | C6: Technology | D6: Technologie | E6: TECH:IT_MSP | F6: IT Services & Managed Services (MSP) | G6: ITâ€‘Dienstleistungen & Managed Services (MSP) | H6: IT Services & MSP | I6: 10 | J6: 15 | K6: 10 | L6: 6 | M6: 68
B7: TECH | C7: Technology | D7: Technologie | E7: TECH:Cyber | F7: Cybersecurity | G7: Cybersecurity | H7: Cybersecurity | I7: 18.5 | J7: 21.5 | K7: 13.5 | L7: 10 | M7: 80
B8: TECH | C8: Technology | D8: Technologie | E8: TECH:Cloud_Host | F8: Cloud & Hosting | G8: Cloud & Hosting | H8: Cloud & Hosting | I8: 15 | J8: 24 | K8: 18 | L8: 12 | M8: 82
B9: TECH | C9: Technology | D9: Technologie | E9: TECH:SysInt | F9: Systems Integration | G9: Systemintegration | H9: Systems Integration | I9: 10.5 | J9: 16 | K9: 9 | L9: 6 | M9: 70
B10: TECH | C10: Technology | D10: Technologie | E10: TECH:Ind_SW | F10: Industrial Software (CAD/CAM/PLM) | G10: Industrielle Software (CAD/CAM/PLM) | H10: Industrial Software (CAD/CAM/PLM) | I10: 12.5 | J10: 24 | K10: 12 | L10: 8 | M10: 76
B11: TECH | C11: Technology | D11: Technologie | E11: TECH:IoT_I40 | F11: IoT & Industry 4.0 Platforms | G11: IoT & Industrieâ€‘4.0â€‘Plattformen | H11: IoT & Industry 4.0 Platforms | I11: 14 | J11: 22 | K11: 16 | L11: 12 | M11: 80
B12: TECH | C12: Technology | D12: Technologie | E12: TECH:Emb_SW | F12: Embedded Software | G12: Embeddedâ€‘Software | H12: Embedded Software | I12: 13 | J12: 20 | K12: 11 | L12: 8 | M12: 74
B13: TECH | C13: Technology | D13: Technologie | E13: TECH:Data_AI | F13: Data Platforms & AI Tooling | G13: Datenplattformen & KIâ€‘Tools | H13: Data Platforms & AI Tooling | I13: 21.5 | J13: 30 | K13: 40 | L13: 25 | M13: 92
B14: TECH | C14: Technology | D14: Technologie | E14: TECH:EC_SW | F14: Eâ€‘Commerce Enablement Software | G14: Eâ€‘Commerceâ€‘Enablementâ€‘Software | H14: E-Commerce Enablement Software | I14: 16 | J14: 26 | K14: 16 | L14: 12 | M14: 82
B15: TECH | C15: Technology | D15: Technologie | E15: TECH:DevOps | F15: DevOps & Developer Tools | G15: DevOps & Entwicklerâ€‘Tools | H15: DevOps & Developer Tools | I15: 17.5 | J15: 31.5 | K15: 17.5 | L15: 12 | M15: 84
... B176: HOSP | C176: Hospitality & Leisure | D176: Gastgewerbe & Freizeit | E176: HOSP:Laundry | F176: Industrial Laundry Services | G176: Industrielle WÃ¤schereien | H176: Industrial Laundry Services | I176: 8 | J176: 6 | K176: 10 | L176: 6 | M176: 66
B179: Country_DeltaMultiple
B181: CountryCode | C181: DeltaMultiple
B182: US | C182: 0.2
B183: UK | C183: 0.2
B184: DE | C184: 0.2
B185: NL | C185: 0.1
B186: FR | C186: 0
B187: FI | C187: -0.1
B188: CH | C188: -0.2
B189: CZ | C189: -0.2
B190: HU | C190: -0.2
B191: RO | C191: -0.3
B194: Size_DeltaMultiple (banded by Revenue in EUR, use ONLY a RevMin_EUR column)
B196: RevMin_EUR | C196: DeltaMultiple
B197: 0 | C197: -0.5
B198: 5000000 | C198: -0.2
B199: 15000000 | C199: 0
B200: 50000000 | C200: 0.3
B201: 100000000 | C201: 0.6
B204: Conc_DeltaMultiple (banded by Top-3 %, use ONLY a Top3_MinPct column)
B206: Top3_MinPct | C206: DeltaMultiple
B207: 0 | C207: 0.1
B208: 30 | C208: 0
B209: 45 | C209: -0.3
B210: 60 | C210: -0.6
B212: Keep Top3_MinPct ascending. Same XLOOKUP(..., 1) trick.
...
