Workbook

Sheet STANDARD (Investor Grade)
A1: Tapway Global - Valuation Training Dataset | C1: User Inputs | E1: Blue Cells
C2: API-Fetched Data | E2: Yellow Cells
A3: Standard Version (Investor-Grade Analysis) | C3: Calculated Fields | E3: Green Cells
A5: FREE VERSION - QUICK VALUATION (3-MINUTE ANALYSIS)
A6: USER INPUTS
A7: Metric | B7: Apple | C7: Microsoft | D7: Amazon | E7: Alphabet | F7: Meta | G7: Tesla | H7: NVIDIA | I7: Intel | J7: PepsiCo | K7: Nike | L7: Starbucks | M7: Costco | N7: IBM | O7: Oracle | P7: Qualcomm | Q7: AMD | R7: ServiceNow | S7: PayPal | T7: Booking | U7: GM | V7: Target | W7: Lowe’s | X7: Unilever | Y7: BP | Z7: Shell | AA7: Diageo | AB7: HSBC | AC7: RELX | AD7: Ocado | AE7: AstraZeneca | AF7: Siemens | AG7: SAP | AH7: ASML | AI7: LVMH | AJ7: TotalEnergies | AK7: Schneider Electric | AL7: AXA | AM7: Sanofi | AN7: Allianz | AO7: BASF | AP7: BMW | AQ7: Volkswagen | AR7: Adidas | AS7: Infineon | AT7: Nokia | AU7: Barclays | AV7: Lloyds Banking Group | AW7: Standard Chartered | AX7: Vodafone | AY7: BT Group | AZ7: Experian | BA7: Smith & Nephew | BB7: Danone | BC7: Heineken | BD7: Rolls-Royce | BE7: Airbus | BF7: RELX | BG7: RELX Group | BH7: Siemens Energy | BI7: Nestlé
A8: Sector | B8: Consumer Electronics Brands | C8: Cloud & Hosting | D8: E-Commerce Logistics | E8: Data Platforms & AI Tooling | F8: Digital Media/Performance Agencies | G8: Automotive Suppliers (Tier-1/2/3) | H8: Embedded Software | I8: Embedded Software | J8: Food & Beverage Manufacturing | K8: Apparel & Textiles | L8: Restaurant Groups & QSR | M8: Omnichannel Retailers | N8: IT Services & MSP | O8: Data Platforms & AI Tooling | P8: Embedded Software | Q8: Embedded Software | R8: B2B SaaS | S8: Payment Service Providers (SME) | T8: Travel Agencies & Tour Ops | U8: Automotive Suppliers (Tier-1/2/3) | V8: Omnichannel Retailers | W8: DIY/Building Materials Retail | X8: Household & Cleaning Products | Y8: Fuel Stations & Convenience | Z8: Fuel Stations & Convenience | AA8: Breweries & Beverage Producers | AB8: FX & Brokerage (MiFID firms) | AC8: Publishers & Niche Media | AD8: E-Commerce Logistics | AE8: Pharma Manufacturing (SME) | AF8: Industrial Automation & Robotics | AG8: Vertical SaaS | AH8: Machinery & Equipment | AI8: Personal Care & Cosmetics | AJ8: Fuel Stations & Convenience | AK8: Industrial Automation & Robotics | AL8: Insurance Brokerage (Makler) | AM8: Pharma Manufacturing (SME) | AN8: Insurance Brokerage (Makler) | AO8: Specialty Chemicals | AP8: Automotive Suppliers (Tier-1/2/3) | AQ8: Automotive Suppliers (Tier-1/2/3) | AR8: Sporting Goods | AS8: Embedded Software | AT8: ISPs & Regional Telecoms | AU8: FX & Brokerage (MiFID firms) | AV8: FX & Brokerage (MiFID firms) | AW8: FX & Brokerage (MiFID firms) | AX8: ISPs & Regional Telecoms | AY8: ISPs & Regional Telecoms | AZ8: Data Platforms & AI Tooling | BA8: Medical Devices (SME) | BB8: Food & Beverage Manufacturing | BC8: Breweries & Beverage Producers | BD8: Machinery & Equipment | BE8: Machinery & Equipment | BF8: Publishers & Niche Media | BG8: Publishers & Niche Media | BH8: Grid Services & Electrical Infra | BI8: Food & Beverage Manufacturing | BJ8: Data validation list from =Sector_BaseEBITMultiple[Sector]
A9: Country | B9: US | C9: US | D9: US | E9: US | F9: US | G9: US | H9: US | I9: US | J9: US | K9: US | L9: US | M9: US | N9: US | O9: US | P9: US | Q9: US | R9: US | S9: US | T9: US | U9: US | V9: US | W9: US | X9: UK | Y9: UK | Z9: NL | AA9: UK | AB9: UK | AC9: UK | AD9: UK | AE9: UK | AF9: DE | AG9: DE | AH9: NL | AI9: FR | AJ9: FR | AK9: FR | AL9: FR | AM9: FR | AN9: DE | AO9: DE | AP9: DE | AQ9: DE | AR9: DE | AS9: DE | AT9: FI | AU9: UK | AV9: UK | AW9: UK | AX9: UK | AY9: UK | AZ9: UK | BA9: UK | BB9: FR | BC9: NL | BD9: UK | BE9: FR | BF9: UK | BG9: DE | BH9: NL | BI9: CH | BJ9: ISO code, list from =Country_DeltaMultiple[CountryCode]
A10: Currency | B10: USD | C10: USD | D10: USD | E10: USD | F10: USD | G10: USD | H10: USD | I10: USD | J10: USD | K10: USD | L10: USD | M10: USD | N10: USD | O10: USD | P10: USD | Q10: USD | R10: USD | S10: USD | T10: USD | U10: USD | V10: USD | W10: USD | X10: EUR | Y10: USD | Z10: USD | AA10: GBP | AB10: USD | AC10: GBP | AD10: GBP | AE10: USD | AF10: EUR | AG10: EUR | AH10: EUR | AI10: EUR | AJ10: USD | AK10: EUR | AL10: EUR | AM10: EUR | AN10: EUR | AO10: EUR | AP10: EUR | AQ10: EUR | AR10: EUR | AS10: EUR | AT10: EUR | AU10: GBP | AV10: GBP | AW10: USD | AX10: EUR | AY10: GBP | AZ10: USD | BA10: USD | BB10: EUR | BC10: EUR | BD10: GBP | BE10: EUR | BF10: GBP | BG10: EUR | BH10: EUR | BI10: CHF | BJ10: List from =FX_To_EUR[Currency]
A11: Employees | B11: 161000 | C11: 221000 | D11: 1525000 | E11: 182000 | F11: 67000 | G11: 140000 | H11: 29600 | I11: 124800 | J11: 318000 | K11: 83700 | L11: 381000 | M11: 316000 | N11: 288000 | O11: 164000 | P11: 51000 | Q11: 26000 | R11: 22000 | S11: 30000 | T11: 24000 | U11: 163000 | V11: 440000 | W11: 300000 | X11: 148000 | Y11: 87800 | Z11: 93000 | AA11: 30000 | AB11: 214000 | AC11: 36000 | AD11: 20000 | AE11: 83100 | AF11: 311000 | AG11: 107000 | AH11: 42000 | AI11: 213000 | AJ11: 101000 | AK11: 168000 | AL11: 93000 | AM11: 91000 | AN11: 159000 | AO11: 111000 | AP11: 154950 | AQ11: 684000 | AR11: 59258 | AS11: 58600 | AT11: 86000 | AU11: 87000 | AV11: 61000 | AW11: 83000 | AX11: 94000 | AY11: 106000 | AZ11: 21700 | BA11: 18000 | BB11: 96000 | BC11: 85000 | BD11: 42000 | BE11: 134000 | BF11: 36000 | BG11: 92000 | BH11: 67000 | BI11: 273000 | BJ11: Number > 0
A12: Revenue Y1 | B12: 394328000000 | C12: 211915000000 | D12: 574785000000 | E12: 307394000000 | F12: 134902000000 | G12: 96773000000 | H12: 60922000000 | I12: 54228000000 | J12: 91471000000 | K12: 51217000000 | L12: 35976000000 | M12: 242290000000 | N12: 61860000000 | O12: 49900000000 | P12: 36400000000 | Q12: 22700000000 | R12: 8971000000 | S12: 29771000000 | T12: 21365000000 | U12: 171842000000 | V12: 106005000000 | W12: 86377000000 | X12: 59604000000 | Y12: 248891000000 | Z12: 323183000000 | AA12: 17096000000 | AB12: 66100000000 | AC12: 9200000000 | AD12: 2833000000 | AE12: 45811000000 | AF12: 77769000000 | AG12: 31207000000 | AH12: 27559000000 | AI12: 86153000000 | AJ12: 237120000000 | AK12: 36000000000 | AL12: 102000000000 | AM12: 43070000000 | AN12: 161700000000 | AO12: 68900000000 | AP12: 155498000000 | AQ12: 322284000000 | AR12: 21427000000 | AS12: 16300000000 | AT12: 24900000000 | AU12: 25400000000 | AV12: 17000000000 | AW12: 19300000000 | AX12: 45710000000 | AY12: 20700000000 | AZ12: 7170000000 | BA12: 5550000000 | BB12: 27600000000 | BC12: 36400000000 | BD12: 16500000000 | BE12: 65400000000 | BF12: 9200000000 | BG12: 31000000000 | BH12: 18200000000 | BI12: 93000000000
A13: Revenue Y2 | B13: 365817000000 | C13: 198270000000 | D13: 513983000000 | E13: 282836000000 | F13: 116609000000 | G13: 81462000000 | H13: 26974000000 | I13: 63054000000 | J13: 86392000000 | K13: 46710000000 | L13: 32250000000 | M13: 226954000000 | N13: 60530000000 | O13: 42400000000 | P13: 44200000000 | Q13: 23600000000 | R13: 7245000000 | S13: 27518000000 | T13: 17090000000 | U13: 156735000000 | V13: 109120000000 | W13: 97059000000 | X13: 60073000000 | Y13: 239893000000 | Z13: 386201000000 | AA13: 15452000000 | AB13: 61600000000 | AC13: 8553000000 | AD13: 2500000000 | AE13: 44351000000 | AF13: 72000000000 | AG13: 30871000000 | AH13: 21173000000 | AI13: 79184000000 | AJ13: 263310000000 | AK13: 34200000000 | AL13: 99300000000 | AM13: 42000000000 | AN13: 152700000000 | AO13: 87300000000 | AP13: 142610000000 | AQ13: 279232000000 | AR13: 22511000000 | AS13: 14200000000 | AT13: 26000000000 | AU13: 24900000000 | AV13: 18800000000 | AW13: 18800000000 | AX13: 45580000000 | AY13: 20100000000 | AZ13: 6800000000 | BA13: 5200000000 | BB13: 27700000000 | BC13: 34300000000 | BD13: 12700000000 | BE13: 58800000000 | BF13: 8553000000 | BG13: 29000000000 | BH13: 17700000000 | BI13: 91500000000
A14: Revenue Y3 | B14: 274515000000 | C14: 168088000000 | D14: 469822000000 | E14: 257637000000 | F14: 117929000000 | G14: 53823000000 | H14: 11716000000 | I14: 79024000000 | J14: 79474000000 | K14: 44538000000 | L14: 29061000000 | M14: 195929000000 | N14: 57350000000 | O14: 40500000000 | P14: 33600000000 | Q14: 16400000000 | R14: 5896000000 | S14: 25371000000 | T14: 14141000000 | U14: 127004000000 | V14: 93561000000 | W14: 96250000000 | X14: 52444000000 | Y14: 181587000000 | Z14: 261504000000 | AA14: 13870000000 | AB14: 54300000000 | AC14: 7244000000 | AD14: 2300000000 | AE14: 40700000000 | AF14: 62265000000 | AG14: 27839000000 | AH14: 13979000000 | AI14: 64215000000 | AJ14: 205855000000 | AK14: 31100000000 | AL14: 94000000000 | AM14: 41200000000 | AN14: 148500000000 | AO14: 78600000000 | AP14: 111239000000 | AQ14: 250200000000 | AR14: 19844000000 | AS14: 11100000000 | AT14: 23500000000 | AU14: 21900000000 | AV14: 15800000000 | AW14: 15000000000 | AX14: 45580000000 | AY14: 21000000000 | AZ14: 6400000000 | BA14: 4600000000 | BB14: 24300000000 | BC14: 28000000000 | BD14: 11200000000 | BE14: 52100000000 | BF14: 7244000000 | BG14: 27000000000 | BH14: 17400000000 | BI14: 90500000000
A15: EBIT Y1 | B15: 114301000000 | C15: 88523000000 | D15: 36852000000 | E15: 84293000000 | F15: 46753000000 | G15: 8891000000 | H15: 32972000000 | I15: 1688000000 | J15: 11505000000 | K15: 6690000000 | L15: 5742000000 | M15: 8100000000 | N15: 9300000000 | O15: 15000000000 | P15: 12000000000 | Q15: 1400000000 | R15: 1700000000 | S15: 5000000000 | T15: 7100000000 | U15: 8100000000 | V15: 4100000000 | W15: 13400000000 | X15: 10710000000 | Y15: 27042000000 | Z15: 45348000000 | AA15: 4372000000 | AB15: 24300000000 | AC15: 3200000000 | AD15: -500000000 | AE15: 9600000000 | AF15: 11400000000 | AG15: 8633000000 | AH15: 8319000000 | AI15: 22802000000 | AJ15: 36640000000 | AK15: 6200000000 | AL15: 8900000000 | AM15: 10400000000 | AN15: 14700000000 | AO15: 2200000000 | AP15: 18482000000 | AQ15: 22600000000 | AR15: -216000000 | AS15: 4000000000 | AT15: 2300000000 | AU15: 6300000000 | AV15: 7500000000 | AW15: 4000000000 | AX15: 4800000000 | AY15: 7500000000 | AZ15: 2300000000 | BA15: 1000000000 | BB15: 3200000000 | BC15: 4500000000 | BD15: 1600000000 | BE15: 7400000000 | BF15: 3200000000 | BG15: -400000000 | BH15: 1200000000 | BI15: 17500000000
A16: EBIT Y2 | B16: 108949000000 | C16: 83383000000 | D16: 12248000000 | E16: 74842000000 | F16: 28944000000 | G16: 13656000000 | H16: 13616000000 | I16: 3015000000 | J16: 10123000000 | K16: 6425000000 | L16: 4872000000 | M16: 7400000000 | N16: 8100000000 | O16: 13000000000 | P16: 15300000000 | Q16: 3600000000 | R16: 1200000000 | S16: 4200000000 | T16: 5200000000 | U16: 10000000000 | V16: 4900000000 | W16: 15000000000 | X16: 9725000000 | Y16: 25163000000 | Z16: 60404000000 | AA16: 4005000000 | AB16: 19300000000 | AC16: 2900000000 | AD16: -400000000 | AE16: 9400000000 | AF16: 9800000000 | AG16: 7914000000 | AH16: 6463000000 | AI16: 19550000000 | AJ16: 55390000000 | AK16: 5500000000 | AL16: 7600000000 | AM16: 9800000000 | AN16: 13400000000 | AO16: 6900000000 | AP16: 13871000000 | AQ16: 22500000000 | AR16: 669000000 | AS16: 3400000000 | AT16: 2600000000 | AU16: 5900000000 | AV16: 8400000000 | AW16: 3500000000 | AX16: 5000000000 | AY16: 7000000000 | AZ16: 2100000000 | BA16: 900000000 | BB16: 3100000000 | BC16: 4000000000 | BD16: 1200000000 | BE16: 5600000000 | BF16: 2900000000 | BG16: -900000000 | BH16: 900000000 | BI16: 17000000000
A17: EBIT Y3 | B17: 66288000000 | C17: 69916000000 | D17: 24879000000 | E17: 54396000000 | F17: 32671000000 | G17: 6523000000 | H17: 4224000000 | I17: 21110000000 | J17: 9776000000 | K17: 5727000000 | L17: 4847000000 | M17: 6100000000 | N17: 6500000000 | O17: 12400000000 | P17: 10400000000 | Q17: 2500000000 | R17: 700000000 | S17: 3800000000 | T17: 4100000000 | U17: 6600000000 | V17: 3900000000 | W17: 14100000000 | X17: 8708000000 | Y17: 13001000000 | Z17: 20399000000 | AA17: 3727000000 | AB17: 13200000000 | AC17: 2500000000 | AD17: -300000000 | AE17: 8300000000 | AF17: 6749000000 | AG17: 6709000000 | AH17: 4723000000 | AI17: 14040000000 | AJ17: 30670000000 | AK17: 4800000000 | AL17: 6700000000 | AM17: 9200000000 | AN17: 12300000000 | AO17: 6800000000 | AP17: 12893000000 | AQ17: 19300000000 | AR17: 1990000000 | AS17: 2100000000 | AT17: 2100000000 | AU17: 5000000000 | AV17: 6900000000 | AW17: 2800000000 | AX17: 5200000000 | AY17: 7600000000 | AZ17: 1900000000 | BA17: 800000000 | BB17: 2700000000 | BC17: 3300000000 | BD17: -1200000000 | BE17: 4800000000 | BF17: 2500000000 | BG17: -1500000000 | BH17: 600000000 | BI17: 16500000000
A18: Revenue F1 | B18: 420000000000 | C18: 230000000000 | D18: 620000000000 | E18: 340000000000 | F18: 155000000000 | G18: 110000000000 | H18: 72000000000 | I18: 58000000000 | J18: 96000000000 | K18: 54000000000 | L18: 38000000000 | M18: 260000000000 | N18: 64000000000 | O18: 53000000000 | P18: 38000000000 | Q18: 26000000000 | R18: 11000000000 | S18: 32000000000 | T18: 24000000000 | U18: 180000000000 | V18: 112000000000 | W18: 90000000000 | X18: 63000000000 | Y18: 260000000000 | Z18: 345000000000 | AA18: 18500000000 | AB18: 70000000000 | AC18: 9800000000 | AD18: 3100000000 | AE18: 48000000000 | AF18: 82000000000 | AG18: 34000000000 | AH18: 30000000000 | AI18: 92000000000 | AJ18: 260000000000 | AK18: 38500000000 | AL18: 108000000000 | AM18: 46000000000 | AN18: 170000000000 | AO18: 72000000000 | AP18: 165000000000 | AQ18: 340000000000 | AR18: 23500000000 | AS18: 18000000000 | AT18: 26000000000 | AU18: 27000000000 | AV18: 18500000000 | AW18: 20500000000 | AX18: 47000000000 | AY18: 21500000000 | AZ18: 7600000000 | BA18: 5800000000 | BB18: 29000000000 | BC18: 38500000000 | BD18: 18500000000 | BE18: 70000000000 | BF18: 9800000000 | BG18: 33000000000 | BH18: 19500000000 | BI18: 96000000000
A19: Revenue F2 | B19: 450000000000 | C19: 260000000000 | D19: 680000000000 | E19: 380000000000 | F19: 180000000000 | G19: 125000000000 | H19: 85000000000 | I19: 62000000000 | J19: 102000000000 | K19: 58000000000 | L19: 41000000000 | M19: 280000000000 | N19: 67000000000 | O19: 58000000000 | P19: 41000000000 | Q19: 30000000000 | R19: 13500000000 | S19: 35000000000 | T19: 27000000000 | U19: 195000000000 | V19: 118000000000 | W19: 95000000000 | X19: 67000000000 | Y19: 280000000000 | Z19: 365000000000 | AA19: 20000000000 | AB19: 75000000000 | AC19: 10500000000 | AD19: 3500000000 | AE19: 52000000000 | AF19: 88000000000 | AG19: 38000000000 | AH19: 34000000000 | AI19: 98000000000 | AJ19: 285000000000 | AK19: 42000000000 | AL19: 115000000000 | AM19: 50000000000 | AN19: 182000000000 | AO19: 76000000000 | AP19: 178000000000 | AQ19: 365000000000 | AR19: 25500000000 | AS19: 20000000000 | AT19: 28000000000 | AU19: 29000000000 | AV19: 20000000000 | AW19: 22500000000 | AX19: 49000000000 | AY19: 23000000000 | AZ19: 8200000000 | BA19: 6200000000 | BB19: 31000000000 | BC19: 41000000000 | BD19: 21000000000 | BE19: 75000000000 | BF19: 10500000000 | BG19: 36000000000 | BH19: 21000000000 | BI19: 98500000000
A20: Revenue F3 | B20: 480000000000 | C20: 300000000000 | D20: 750000000000 | E20: 420000000000 | F20: 210000000000 | G20: 145000000000 | H20: 100000000000 | I20: 68000000000 | J20: 110000000000 | K20: 62000000000 | L20: 45000000000 | M20: 300000000000 | N20: 70000000000 | O20: 64000000000 | P20: 45000000000 | Q20: 35000000000 | R20: 16500000000 | S20: 39000000000 | T20: 31000000000 | U20: 215000000000 | V20: 125000000000 | W20: 102000000000 | X20: 72000000000 | Y20: 305000000000 | Z20: 390000000000 | AA20: 22000000000 | AB20: 82000000000 | AC20: 11500000000 | AD20: 4200000000 | AE20: 58000000000 | AF20: 95000000000 | AG20: 43000000000 | AH20: 39000000000 | AI20: 105000000000 | AJ20: 315000000000 | AK20: 46000000000 | AL20: 123000000000 | AM20: 55000000000 | AN20: 195000000000 | AO20: 82000000000 | AP20: 192000000000 | AQ20: 395000000000 | AR20: 28000000000 | AS20: 22500000000 | AT20: 30500000000 | AU20: 31500000000 | AV20: 22000000000 | AW20: 25000000000 | AX20: 52000000000 | AY20: 25000000000 | AZ20: 9000000000 | BA20: 6800000000 | BB20: 33500000000 | BC20: 44500000000 | BD20: 24500000000 | BE20: 82000000000 | BF20: 11500000000 | BG20: 40000000000 | BH20: 23000000000 | BI20: 102000000000
A21: EBIT F1 | B21: 120000000000 | C21: 98000000000 | D21: 42000000000 | E21: 95000000000 | F21: 55000000000 | G21: 12000000000 | H21: 38000000000 | I21: 3500000000 | J21: 12500000000 | K21: 7200000000 | L21: 6500000000 | M21: 9000000000 | N21: 9800000000 | O21: 16500000000 | P21: 12500000000 | Q21: 3000000000 | R21: 2200000000 | S21: 5500000000 | T21: 8200000000 | U21: 9800000000 | V21: 4600000000 | W21: 14500000000 | X21: 11500000000 | Y21: 30000000000 | Z21: 48000000000 | AA21: 4800000000 | AB21: 26500000000 | AC21: 3500000000 | AD21: 200000000 | AE21: 10500000000 | AF21: 12500000000 | AG21: 9500000000 | AH21: 9800000000 | AI21: 24500000000 | AJ21: 40000000000 | AK21: 7000000000 | AL21: 9800000000 | AM21: 11500000000 | AN21: 16000000000 | AO21: 3500000000 | AP21: 19500000000 | AQ21: 24500000000 | AR21: 1500000000 | AS21: 4600000000 | AT21: 2800000000 | AU21: 7000000000 | AV21: 8200000000 | AW21: 4600000000 | AX21: 5200000000 | AY21: 8200000000 | AZ21: 2600000000 | BA21: 1200000000 | BB21: 3600000000 | BC21: 5200000000 | BD21: 2400000000 | BE21: 8200000000 | BF21: 3500000000 | BG21: 500000000 | BH21: 1800000000 | BI21: 18500000000
A22: EBIT F2 | B22: 130000000000 | C22: 112000000000 | D22: 50000000000 | E22: 110000000000 | F22: 65000000000 | G22: 15000000000 | H22: 45000000000 | I22: 4800000000 | J22: 13800000000 | K22: 8200000000 | L22: 7200000000 | M22: 10200000000 | N22: 10500000000 | O22: 18500000000 | P22: 14000000000 | Q22: 4500000000 | R22: 3000000000 | S22: 6200000000 | T22: 9500000000 | U22: 11500000000 | V22: 5200000000 | W22: 16000000000 | X22: 12800000000 | Y22: 34000000000 | Z22: 53000000000 | AA22: 5400000000 | AB22: 30000000000 | AC22: 4000000000 | AD22: 350000000 | AE22: 11500000000 | AF22: 14500000000 | AG22: 11000000000 | AH22: 11500000000 | AI22: 27500000000 | AJ22: 46000000000 | AK22: 8200000000 | AL22: 11200000000 | AM22: 13000000000 | AN22: 18000000000 | AO22: 4800000000 | AP22: 22500000000 | AQ22: 28000000000 | AR22: 2300000000 | AS22: 5200000000 | AT22: 3200000000 | AU22: 8200000000 | AV22: 9600000000 | AW22: 5500000000 | AX22: 6000000000 | AY22: 9500000000 | AZ22: 3000000000 | BA22: 1500000000 | BB22: 4100000000 | BC22: 6000000000 | BD22: 3100000000 | BE22: 9500000000 | BF22: 4000000000 | BG22: 1500000000 | BH22: 2400000000 | BI22: 19500000000
A23: EBIT F3 | B23: 145000000000 | C23: 130000000000 | D23: 60000000000 | E23: 125000000000 | F23: 78000000000 | G23: 19000000000 | H23: 54000000000 | I23: 6200000000 | J23: 15000000000 | K23: 9500000000 | L23: 8200000000 | M23: 11500000000 | N23: 11200000000 | O23: 21000000000 | P23: 16000000000 | Q23: 6500000000 | R23: 4200000000 | S23: 7000000000 | T23: 11200000000 | U23: 13500000000 | V23: 6000000000 | W23: 17800000000 | X23: 14500000000 | Y23: 38000000000 | Z23: 60000000000 | AA23: 6200000000 | AB23: 35000000000 | AC23: 4600000000 | AD23: 600000000 | AE23: 13000000000 | AF23: 17000000000 | AG23: 13000000000 | AH23: 13500000000 | AI23: 31000000000 | AJ23: 53000000000 | AK23: 9600000000 | AL23: 13000000000 | AM23: 15000000000 | AN23: 20500000000 | AO23: 6500000000 | AP23: 26000000000 | AQ23: 32000000000 | AR23: 3500000000 | AS23: 6100000000 | AT23: 3800000000 | AU23: 9800000000 | AV23: 11200000000 | AW23: 6700000000 | AX23: 7200000000 | AY23: 11000000000 | AZ23: 3600000000 | BA23: 1900000000 | BB23: 4800000000 | BC23: 7200000000 | BD23: 4200000000 | BE23: 11000000000 | BF23: 4600000000 | BG23: 2800000000 | BH23: 3200000000 | BI23: 21000000000
A24: Top-3 % | B24: 25 | C24: 20 | D24: 30 | E24: 35 | F24: 40 | G24: 50 | H24: 40 | I24: 35 | J24: 30 | K24: 45 | L24: 25 | M24: 20 | N24: 35 | O24: 30 | P24: 45 | Q24: 40 | R24: 25 | S24: 50 | T24: 20 | U24: 45 | V24: 25 | W24: 30 | X24: 40 | Y24: 50 | Z24: 55 | AA24: 40 | AB24: 30 | AC24: 25 | AD24: 45 | AE24: 35 | AF24: 30 | AG24: 35 | AH24: 45 | AI24: 25 | AJ24: 50 | AK24: 40 | AL24: 30 | AM24: 35 | AN24: 25 | AO24: 40 | AP24: 45 | AQ24: 50 | AR24: 40 | AS24: 45 | AT24: 35 | AU24: 30 | AV24: 25 | AW24: 30 | AX24: 35 | AY24: 30 | AZ24: 25 | BA24: 40 | BB24: 45 | BC24: 50 | BD24: 50 | BE24: 45 | BF24: 25 | BG24: 55 | BH24: 40 | BI24: 35 | BJ24: Number 0–100.
A25: Founder dependency high? | B25: No | C25: No | D25: Yes | E25: Yes | F25: Yes | G25: Yes | H25: No | I25: No | J25: No | K25: No | L25: No | M25: No | N25: No | O25: No | P25: No | Q25: No | R25: No | S25: Yes | T25: No | U25: No | V25: No | W25: No | X25: No | Y25: No | Z25: No | AA25: No | AB25: No | AC25: No | AD25: No | AE25: No | AF25: No | AG25: No | AH25: No | AI25: No | AJ25: No | AK25: No | AL25: No | AM25: No | AN25: No | AO25: No | AP25: No | AQ25: No | AR25: No | AS25: No | AT25: No | AU25: No | AV25: No | AW25: No | AX25: No | AY25: No | AZ25: No | BA25: No | BB25: No | BC25: No | BD25: No | BE25: No | BF25: No | BG25: No | BH25: No | BI25: No | BJ25: YES/NO
A26: Supplier dependency high? | B26: No | C26: No | D26: Yes | E26: No | F26: No | G26: Yes | H26: Yes | I26: Yes | J26: No | K26: Yes | L26: Yes | M26: No | N26: No | O26: No | P26: Yes | Q26: Yes | R26: No | S26: Yes | T26: No | U26: Yes | V26: Yes | W26: Yes | X26: Yes | Y26: Yes | Z26: Yes | AA26: Yes | AB26: No | AC26: No | AD26: Yes | AE26: No | AF26: Yes | AG26: No | AH26: Yes | AI26: No | AJ26: Yes | AK26: Yes | AL26: No | AM26: No | AN26: No | AO26: Yes | AP26: Yes | AQ26: Yes | AR26: Yes | AS26: Yes | AT26: Yes | AU26: No | AV26: No | AW26: No | AX26: Yes | AY26: Yes | AZ26: No | BA26: Yes | BB26: Yes | BC26: Yes | BD26: Yes | BE26: Yes | BF26: No | BG26: Yes | BH26: Yes | BI26: No | BJ26: YES/NO
A27: Key staff retention plan? | B27: Yes | C27: Yes | D27: Yes | E27: Yes | F27: Yes | G27: Yes | H27: Yes | I27: Yes | J27: Yes | K27: Yes | L27: Yes | M27: Yes | N27: Yes | O27: Yes | P27: Yes | Q27: Yes | R27: Yes | S27: Yes | T27: Yes | U27: Yes | V27: Yes | W27: Yes | X27: Yes | Y27: Yes | Z27: Yes | AA27: Yes | AB27: Yes | AC27: Yes | AD27: Yes | AE27: Yes | AF27: Yes | AG27: Yes | AH27: Yes | AI27: Yes | AJ27: Yes | AK27: Yes | AL27: Yes | AM27: Yes | AN27: Yes | AO27: Yes | AP27: Yes | AQ27: Yes | AR27: Yes | AS27: Yes | AT27: Yes | AU27: Yes | AV27: Yes | AW27: Yes | AX27: Yes | AY27: Yes | AZ27: Yes | BA27: Yes | BB27: Yes | BC27: Yes | BD27: Yes | BE27: Yes | BF27: Yes | BG27: Yes | BH27: Yes | BI27: Yes | BJ27: YES/NO
A28: Documentation readiness | B28: Full | C28: Full | D28: Full | E28: Full | F28: Full | G28: Full | H28: Full | I28: Full | J28: Full | K28: Full | L28: Full | M28: Full | N28: Full | O28: Full | P28: Full | Q28: Full | R28: Full | S28: Full | T28: Full | U28: Full | V28: Full | W28: Full | X28: Full | Y28: Full | Z28: Full | AA28: Full | AB28: Full | AC28: Full | AD28: Full | AE28: Full | AF28: Full | AG28: Full | AH28: Full | AI28: Full | AJ28: Full | AK28: Full | AL28: Full | AM28: Full | AN28: Full | AO28: Full | AP28: Full | AQ28: Full | AR28: Full | AS28: Full | AT28: Full | AU28: Full | AV28: Full | AW28: Full | AX28: Full | AY28: Full | AZ28: Full | BA28: Full | BB28: Full | BC28: Full | BD28: Full | BE28: Full | BF28: Full | BG28: Full | BH28: Full | BI28: Full | BJ28: None/Partial/Full
A29: Seller flexibility (earn-out/vendor finance) | B29: High | C29: High | D29: Medium | E29: High | F29: Medium | G29: Medium | H29: High | I29: Medium | J29: Medium | K29: Medium | L29: Low | M29: Medium | N29: Medium | O29: Medium | P29: High | Q29: High | R29: High | S29: Medium | T29: High | U29: Medium | V29: Low | W29: Medium | X29: Medium | Y29: Medium | Z29: Medium | AA29: Medium | AB29: Low | AC29: High | AD29: Low | AE29: High | AF29: Medium | AG29: High | AH29: High | AI29: High | AJ29: Medium | AK29: High | AL29: High | AM29: High | AN29: High | AO29: Medium | AP29: Medium | AQ29: Medium | AR29: Medium | AS29: High | AT29: Medium | AU29: Low | AV29: Low | AW29: Low | AX29: Low | AY29: Low | AZ29: High | BA29: Medium | BB29: Medium | BC29: Medium | BD29: Medium | BE29: High | BF29: High | BG29: Medium | BH29: Medium | BI29: High
A30: Target timeline | B30: 3 | C30: 3 | D30: 4 | E30: 3 | F30: 4 | G30: 6 | H30: 3 | I30: 6 | J30: 4 | K30: 5 | L30: 6 | M30: 4 | N30: 6 | O30: 5 | P30: 4 | Q30: 4 | R30: 3 | S30: 6 | T30: 3 | U30: 6 | V30: 6 | W30: 5 | X30: 4 | Y30: 6 | Z30: 6 | AA30: 4 | AB30: 5 | AC30: 3 | AD30: 7 | AE30: 3 | AF30: 5 | AG30: 4 | AH30: 3 | AI30: 3 | AJ30: 6 | AK30: 4 | AL30: 4 | AM30: 3 | AN30: 4 | AO30: 6 | AP30: 5 | AQ30: 6 | AR30: 6 | AS30: 4 | AT30: 5 | AU30: 7 | AV30: 6 | AW30: 7 | AX30: 6 | AY30: 6 | AZ30: 3 | BA30: 4 | BB30: 4 | BC30: 4 | BD30: 6 | BE30: 4 | BF30: 3 | BG30: 7 | BH30: 5 | BI30: 3 | BJ30: months, number
A31: BACKEND HELPERS & LOOKUPS
A32: FX rate | B32: =VLOOKUP(B10,'Reference Data sheet'!$B$216:$C$222,2,FALSE) -> 0.93 | C32: =VLOOKUP(C10,'Reference Data sheet'!$B$216:$C$222,2,FALSE) -> 0.93 | D32: =VLOOKUP(D10,'Reference Data sheet'!$B$216:$C$222,2,FALSE) -> 0.93 | E32: =VLOOKUP(E10,'Reference Data sheet'!$B$216:$C$222,2,FALSE) -> 0.93 | F32: =VLOOKUP(F10,'Reference Data sheet'!$B$216:$C$222,2,FALSE) -> 0.93 | G32: =VLOOKUP(G10,'Reference Data sheet'!$B$216:$C$222,2,FALSE) -> 0.93 | H32: =VLOOKUP(H10,'Reference Data sheet'!$B$216:$C$222,2,FALSE) -> 0.93 | I32: =VLOOKUP(I10,'Reference Data sheet'!$B$216:$C$222,2,FALSE) -> 0.93 | ... BI32: =VLOOKUP(BI10,'Reference Data sheet'!$B$216:$C$222,2,FALSE) -> 1.04 | BJ32: Lookup from Table 5 - Reference Data Sheet
A33: Rev AVG EUR | B33: =AVERAGE(B12:B14)*B32 -> 3.207446e+11 | C33: =AVERAGE(C12:C14)*C32 -> 179264630000 | D33: =AVERAGE(D12:D14)*D32 -> 483162900000 | E33: =AVERAGE(E12:E14)*E32 -> 262838770000 | F33: =AVERAGE(F12:F14)*F32 -> 1.145264e+11 | G33: =AVERAGE(G12:G14)*G32 -> 7.193798e+10 | H33: =AVERAGE(H12:H14)*H32 -> 30879720000 | I33: =AVERAGE(I12:I14)*I32 -> 6.085486e+10 | ... BI33: =AVERAGE(BI12:BI14)*BI32 -> 9.5333333e+10 | BJ33: Average historical Revenue x FX rate
A34: EBIT AVG EUR | B34: =AVERAGE(B15:B17)*B32 -> 8.975678e+10 | C34: =AVERAGE(C15:C17)*C32 -> 74964820000 | D34: =AVERAGE(D15:D17)*D32 -> 2.293349e+10 | E34: =AVERAGE(E15:E17)*E32 -> 66194610000 | F34: =AVERAGE(F15:F17)*F32 -> 33594080000 | G34: =AVERAGE(G15:G17)*G32 -> 9011700000 | H34: =AVERAGE(H15:H17)*H32 -> 1.575172e+10 | I34: =AVERAGE(I15:I17)*I32 -> 8.00203e+09 | ... BI34: =AVERAGE(BI15:BI17)*BI32 -> 17680000000 | BJ34: Average historical EBIT x FX rate
A35: EBIT Margin | B35: =IFERROR(B34/B33,0) -> 0.27983879 | C35: =IFERROR(C34/C33,0) -> 0.41817965 | D35: =IFERROR(D34/D33,0) -> 0.047465337 | E35: =IFERROR(E34/E33,0) -> 0.25184492 | F35: =IFERROR(F34/F33,0) -> 0.29333045 | G35: =IFERROR(G34/G33,0) -> 0.12527041 | H35: =IFERROR(H34/H33,0) -> 0.51009918 | I35: =IFERROR(I34/I33,0) -> 0.13149369 | ... BI35: =IFERROR(BI34/BI33,0) -> 0.18545455
A36: EBIT CAGR | B36: =IFERROR(POWER(B17/B15,0.5)-1,0) -> -0.23846049 | C36: =IFERROR(POWER(C17/C15,0.5)-1,0) -> -0.11128968 | D36: =IFERROR(POWER(D17/D15,0.5)-1,0) -> -0.17835176 | E36: =IFERROR(POWER(E17/E15,0.5)-1,0) -> -0.19668158 | F36: =IFERROR(POWER(F17/F15,0.5)-1,0) -> -0.16405737 | G36: =IFERROR(POWER(G17/G15,0.5)-1,0) -> -0.14345855 | H36: =IFERROR(POWER(H17/H15,0.5)-1,0) -> -0.64207725 | I36: =IFERROR(POWER(I17/I15,0.5)-1,0) -> 2.5363716 | ... BI36: =IFERROR(POWER(BI17/BI15,0.5)-1,0) -> -0.028991688
A37: Volatility | B37: =IFERROR(STDEV(B15:B17)/AVERAGE(B15:B17),0) -> 0.27262496 | C37: =IFERROR(STDEV(C15:C17)/AVERAGE(C15:C17),0) -> 0.11920782 | D37: =IFERROR(STDEV(D15:D17)/AVERAGE(D15:D17),0) -> 0.49893076 | E37: =IFERROR(STDEV(E15:E17)/AVERAGE(E15:E17),0) -> 0.21470065 | F37: =IFERROR(STDEV(F15:F17)/AVERAGE(F15:F17),0) -> 0.26002647 | G37: =IFERROR(STDEV(G15:G17)/AVERAGE(G15:G17),0) -> 0.37492308 | H37: =IFERROR(STDEV(H15:H17)/AVERAGE(H15:H17),0) -> 0.86548259 | I37: =IFERROR(STDEV(I15:I17)/AVERAGE(I15:I17),0) -> 1.2610541 | ... BI37: =IFERROR(STDEV(BI15:BI17)/AVERAGE(BI15:BI17),0) -> 0.029411765
A38: Rev CAGR | B38: =IFERROR(POWER(B14/B12,0.5)-1,0) -> -0.16563855 | C38: =IFERROR(POWER(C14/C12,0.5)-1,0) -> -0.10939013 | D38: =IFERROR(POWER(D14/D12,0.5)-1,0) -> -0.09590522 | E38: =IFERROR(POWER(E14/E12,0.5)-1,0) -> -0.084504058 | F38: =IFERROR(POWER(F14/F12,0.5)-1,0) -> -0.065022599 | G38: =IFERROR(POWER(G14/G12,0.5)-1,0) -> -0.25422667 | H38: =IFERROR(POWER(H14/H12,0.5)-1,0) -> -0.56146667 | I38: =IFERROR(POWER(I14/I12,0.5)-1,0) -> 0.20716799 | ... BI38: =IFERROR(POWER(BI14/BI12,0.5)-1,0) -> -0.013532423
A39: Base Multiple Factor | B39: =VLOOKUP(B8,'Reference Data sheet'!$H$3:$M$176,2,FALSE) -> 11 | C39: =VLOOKUP(C8,'Reference Data sheet'!$H$3:$M$176,2,FALSE) -> 15 | D39: =VLOOKUP(D8,'Reference Data sheet'!$H$3:$M$176,2,FALSE) -> 11.5 | E39: =VLOOKUP(E8,'Reference Data sheet'!$H$3:$M$176,2,FALSE) -> 21.5 | F39: =VLOOKUP(F8,'Reference Data sheet'!$H$3:$M$176,2,FALSE) -> 10.5 | G39: =VLOOKUP(G8,'Reference Data sheet'!$H$3:$M$176,2,FALSE) -> 7.5 | H39: =VLOOKUP(H8,'Reference Data sheet'!$H$3:$M$176,2,FALSE) -> 13 | I39: =VLOOKUP(I8,'Reference Data sheet'!$H$3:$M$176,2,FALSE) -> 13 | ... BI39: =VLOOKUP(BI8,'Reference Data sheet'!$H$3:$M$176,2,FALSE) -> 12 | BJ39: Lookup from Table 1 - Reference Data Sheet
A40: Country Risk Factor | B40: =VLOOKUP(B9,'Reference Data sheet'!$B$181:$C$191,2,FALSE) -> 0.2 | C40: =VLOOKUP(C9,'Reference Data sheet'!$B$181:$C$191,2,FALSE) -> 0.2 | D40: =VLOOKUP(D9,'Reference Data sheet'!$B$181:$C$191,2,FALSE) -> 0.2 | E40: =VLOOKUP(E9,'Reference Data sheet'!$B$181:$C$191,2,FALSE) -> 0.2 | F40: =VLOOKUP(F9,'Reference Data sheet'!$B$181:$C$191,2,FALSE) -> 0.2 | G40: =VLOOKUP(G9,'Reference Data sheet'!$B$181:$C$191,2,FALSE) -> 0.2 | H40: =VLOOKUP(H9,'Reference Data sheet'!$B$181:$C$191,2,FALSE) -> 0.2 | I40: =VLOOKUP(I9,'Reference Data sheet'!$B$181:$C$191,2,FALSE) -> 0.2 | ... BI40: =VLOOKUP(BI9,'Reference Data sheet'!$B$181:$C$191,2,FALSE) -> -0.2 | BJ40: Lookup from Table 2 - Reference Data Sheet
A41: Size Adjustment Factor | B41: =IF(AVERAGE(B12:B14)<='Reference Data sheet'!$B198,'Reference Data sheet'!$C198,IF(AVERAGE(B12:B14)<='Reference Data sheet'!$B199,'Reference Data sheet'!$C199,IF(AVERAGE(B12:B14)<='Reference Data sheet'!$B200,'Reference Data sheet'!$C200,'Reference Data sheet'!$C201))) -> 0.6 | C41: =IF(AVERAGE(C12:C14)<='Reference Data sheet'!$B198,'Reference Data sheet'!$C198,IF(AVERAGE(C12:C14)<='Reference Data sheet'!$B199,'Reference Data sheet'!$C199,IF(AVERAGE(C12:C14)<='Reference Data sheet'!$B200,'Reference Data sheet'!$C200,'Reference Data sheet'!$C201))) -> 0.6 | D41: =IF(AVERAGE(D12:D14)<='Reference Data sheet'!$B198,'Reference Data sheet'!$C198,IF(AVERAGE(D12:D14)<='Reference Data sheet'!$B199,'Reference Data sheet'!$C199,IF(AVERAGE(D12:D14)<='Reference Data sheet'!$B200,'Reference Data sheet'!$C200,'Reference Data sheet'!$C201))) -> 0.6 | E41: =IF(AVERAGE(E12:E14)<='Reference Data sheet'!$B198,'Reference Data sheet'!$C198,IF(AVERAGE(E12:E14)<='Reference Data sheet'!$B199,'Reference Data sheet'!$C199,IF(AVERAGE(E12:E14)<='Reference Data sheet'!$B200,'Reference Data sheet'!$C200,'Reference Data sheet'!$C201))) -> 0.6 | F41: =IF(AVERAGE(F12:F14)<='Reference Data sheet'!$B198,'Reference Data sheet'!$C198,IF(AVERAGE(F12:F14)<='Reference Data sheet'!$B199,'Reference Data sheet'!$C199,IF(AVERAGE(F12:F14)<='Reference Data sheet'!$B200,'Reference Data sheet'!$C200,'Reference Data sheet'!$C201))) -> 0.6 | G41: =IF(AVERAGE(G12:G14)<='Reference Data sheet'!$B198,'Reference Data sheet'!$C198,IF(AVERAGE(G12:G14)<='Reference Data sheet'!$B199,'Reference Data sheet'!$C199,IF(AVERAGE(G12:G14)<='Reference Data sheet'!$B200,'Reference Data sheet'!$C200,'Reference Data sheet'!$C201))) -> 0.6 | H41: =IF(AVERAGE(H12:H14)<='Reference Data sheet'!$B198,'Reference Data sheet'!$C198,IF(AVERAGE(H12:H14)<='Reference Data sheet'!$B199,'Reference Data sheet'!$C199,IF(AVERAGE(H12:H14)<='Reference Data sheet'!$B200,'Reference Data sheet'!$C200,'Reference Data sheet'!$C201))) -> 0.6 | I41: =IF(AVERAGE(I12:I14)<='Reference Data sheet'!$B198,'Reference Data sheet'!$C198,IF(AVERAGE(I12:I14)<='Reference Data sheet'!$B199,'Reference Data sheet'!$C199,IF(AVERAGE(I12:I14)<='Reference Data sheet'!$B200,'Reference Data sheet'!$C200,'Reference Data sheet'!$C201))) -> 0.6 | ... BI41: =IF(AVERAGE(BI12:BI14)<='Reference Data sheet'!$B198,'Reference Data sheet'!$C198,IF(AVERAGE(BI12:BI14)<='Reference Data sheet'!$B199,'Reference Data sheet'!$C199,IF(AVERAGE(BI12:BI14)<='Reference Data sheet'!$B200,'Reference Data sheet'!$C200,'Reference Data sheet'!$C201))) -> 0.6 | BJ41: Lookup from Table 3 - Reference Data Sheet
...

Sheet Reference Data sheet
B3: sector_id | C3: sector_en | D3: sector_de | E3: subsector_id | F3: subsector_en | G3: subsector_de | H3: Subsector_Name (Updated) | I3: Base_EBIT_Multiple | J3: Target_EBIT_Margin_% | K3: Target_CAGR_% | L3: BandMin | M3: Score
B4: TECH | C4: Technology | D4: Technologie | E4: TECH:SaaS_B2B | F4: B2B SaaS | G4: B2Bâ€‘SaaS | H4: B2B SaaS | I4: 17.5 | J4: 32.5 | K4: 17.5 | L4: 10 | M4: 85
B5: TECH | C5: Technology | D5: Technologie | E5: TECH:SaaS_Vert | F5: Vertical SaaS | G5: Vertikales SaaS | H5: Vertical SaaS | I5: 15 | J5: 28.5 | K5: 21.5 | L5: 12 | M5: 82
B6: TECH | C6: Technology | D6: Technologie | E6: TECH:IT_MSP | F6: IT Services & Managed Services (MSP) | G6: ITâ€‘Dienstleistungen & Managed Services (MSP) | H6: IT Services & MSP | I6: 10 | J6: 15 | K6: 10 | L6: 6 | M6: 68
B7: TECH | C7: Technology | D7: Technologie | E7: TECH:Cyber | F7: Cybersecurity | G7: Cybersecurity | H7: Cybersecurity | I7: 18.5 | J7: 21.5 | K7: 13.5 | L7: 10 | M7: 80
B8: TECH | C8: Technology | D8: Technologie | E8: TECH:Cloud_Host | F8: Cloud & Hosting | G8: Cloud & Hosting | H8: Cloud & Hosting | I8: 15 | J8: 24 | K8: 18 | L8: 12 | M8: 82
B9: TECH | C9: Technology | D9: Technologie | E9: TECH:SysInt | F9: Systems Integration | G9: Systemintegration | H9: Systems Integration | I9: 10.5 | J9: 16 | K9: 9 | L9: 6 | M9: 70
B10: TECH | C10: Technology | D10: Technologie | E10: TECH:Ind_SW | F10: Industrial Software (CAD/CAM/PLM) | G10: Industrielle Software (CAD/CAM/PLM) | H10: Industrial Software (CAD/CAM/PLM) | I10: 12.5 | J10: 24 | K10: 12 | L10: 8 | M10: 76
B11: TECH | C11: Technology | D11: Technologie | E11: TECH:IoT_I40 | F11: IoT & Industry 4.0 Platforms | G11: IoT & Industrieâ€‘4.0â€‘Plattformen | H11: IoT & Industry 4.0 Platforms | I11: 14 | J11: 22 | K11: 16 | L11: 12 | M11: 80
B12: TECH | C12: Technology | D12: Technologie | E12: TECH:Emb_SW | F12: Embedded Software | G12: Embeddedâ€‘Software | H12: Embedded Software | I12: 13 | J12: 20 | K12: 11 | L12: 8 | M12: 74
B13: TECH | C13: Technology | D13: Technologie | E13: TECH:Data_AI | F13: Data Platforms & AI Tooling | G13: Datenplattformen & KIâ€‘Tools | H13: Data Platforms & AI Tooling | I13: 21.5 | J13: 30 | K13: 40 | L13: 25 | M13: 92
B14: TECH | C14: Technology | D14: Technologie | E14: TECH:EC_SW | F14: Eâ€‘Commerce Enablement Software | G14: Eâ€‘Commerceâ€‘Enablementâ€‘Software | H14: E-Commerce Enablement Software | I14: 16 | J14: 26 | K14: 16 | L14: 12 | M14: 82
B15: TECH | C15: Technology | D15: Technologie | E15: TECH:DevOps | F15: DevOps & Developer Tools | G15: DevOps & Entwicklerâ€‘Tools | H15: DevOps & Developer Tools | I15: 17.5 | J15: 31.5 | K15: 17.5 | L15: 12 | M15: 84
... B176: HOSP | C176: Hospitality & Leisure | D176: Gastgewerbe & Freizeit | E176: HOSP:Laundry | F176: Industrial Laundry Services | G176: Industrielle WÃ¤schereien | H176: Industrial Laundry Services | I176: 8 | J176: 6 | K176: 10 | L176: 6 | M176: 66
B179: Country_DeltaMultiple
B181: CountryCode | C181: DeltaMultiple
B182: US | C182: 0.2
B183: UK | C183: 0.2
B184: DE | C184: 0.2
B185: NL | C185: 0.1
B186: FR | C186: 0
B187: FI | C187: -0.1
B188: CH | C188: -0.2
B189: CZ | C189: -0.2
B190: HU | C190: -0.2
B191: RO | C191: -0.3
B194: Size_DeltaMultiple (banded by Revenue in EUR, use ONLY a RevMin_EUR column)
B196: RevMin_EUR | C196: DeltaMultiple
B197: 0 | C197: -0.5
B198: 5000000 | C198: -0.2
B199: 15000000 | C199: 0
B200: 50000000 | C200: 0.3
B201: 100000000 | C201: 0.6
B204: Conc_DeltaMultiple (banded by Top-3 %, use ONLY a Top3_MinPct column)
B206: Top3_MinPct | C206: DeltaMultiple
B207: 0 | C207: 0.1
B208: 30 | C208: 0
B209: 45 | C209: -0.3
B210: 60 | C210: -0.6
B212: Keep Top3_MinPct ascending. Same XLOOKUP(..., 1) trick.
...
